Workbook

Sheet Élèves
A1: Liste de la classe — Synthèse des évaluations
A3: N° | B3: Nom Prénom | C3: BB2 12-05-26 /20 | D3: BB2 12-05-26 /12 | E3: Moyenne /20 | F3: Moyenne /12
A4: 1 | B4: Élève 1 | C4: =IFERROR('BB2 12-05-26'!H47,"") | D4: =IFERROR('BB2 12-05-26'!H48,"") | E4: =IF(C4="","",C4) | F4: =IF(D4="","",D4)
A5: 2 | B5: Élève 2 | C5: =IFERROR('BB2 12-05-26'!K47,"") | D5: =IFERROR('BB2 12-05-26'!K48,"") | E5: =IF(C5="","",C5) | F5: =IF(D5="","",D5)
A6: 3 | B6: Élève 3 | C6: =IFERROR('BB2 12-05-26'!N47,"") | D6: =IFERROR('BB2 12-05-26'!N48,"") | E6: =IF(C6="","",C6) | F6: =IF(D6="","",D6)
A7: 4 | B7: Élève 4 | C7: =IFERROR('BB2 12-05-26'!Q47,"") | D7: =IFERROR('BB2 12-05-26'!Q48,"") | E7: =IF(C7="","",C7) | F7: =IF(D7="","",D7)
A8: 5 | B8: Élève 5 | C8: =IFERROR('BB2 12-05-26'!T47,"") | D8: =IFERROR('BB2 12-05-26'!T48,"") | E8: =IF(C8="","",C8) | F8: =IF(D8="","",D8)
A9: 6 | B9: Élève 6 | C9: =IFERROR('BB2 12-05-26'!W47,"") | D9: =IFERROR('BB2 12-05-26'!W48,"") | E9: =IF(C9="","",C9) | F9: =IF(D9="","",D9)
A10: 7 | B10: Élève 7 | C10: =IFERROR('BB2 12-05-26'!Z47,"") | D10: =IFERROR('BB2 12-05-26'!Z48,"") | E10: =IF(C10="","",C10) | F10: =IF(D10="","",D10)
A11: 8 | B11: Élève 8 | C11: =IFERROR('BB2 12-05-26'!AC47,"") | D11: =IFERROR('BB2 12-05-26'!AC48,"") | E11: =IF(C11="","",C11) | F11: =IF(D11="","",D11)
A12: 9 | B12: Élève 9 | C12: =IFERROR('BB2 12-05-26'!AF47,"") | D12: =IFERROR('BB2 12-05-26'!AF48,"") | E12: =IF(C12="","",C12) | F12: =IF(D12="","",D12)
A13: 10 | B13: Élève 10 | C13: =IFERROR('BB2 12-05-26'!AI47,"") | D13: =IFERROR('BB2 12-05-26'!AI48,"") | E13: =IF(C13="","",C13) | F13: =IF(D13="","",D13)
A14: 11 | B14: Élève 11 | C14: =IFERROR('BB2 12-05-26'!AL47,"") | D14: =IFERROR('BB2 12-05-26'!AL48,"") | E14: =IF(C14="","",C14) | F14: =IF(D14="","",D14)
A15: 12 | B15: Élève 12 | C15: =IFERROR('BB2 12-05-26'!AO47,"") | D15: =IFERROR('BB2 12-05-26'!AO48,"") | E15: =IF(C15="","",C15) | F15: =IF(D15="","",D15)
A16: 13 | B16: Élève 13 | C16: =IFERROR('BB2 12-05-26'!AR47,"") | D16: =IFERROR('BB2 12-05-26'!AR48,"") | E16: =IF(C16="","",C16) | F16: =IF(D16="","",D16)
A17: 14 | B17: Élève 14 | C17: =IFERROR('BB2 12-05-26'!AU47,"") | D17: =IFERROR('BB2 12-05-26'!AU48,"") | E17: =IF(C17="","",C17) | F17: =IF(D17="","",D17)
A18: 15 | B18: Élève 15 | C18: =IFERROR('BB2 12-05-26'!AX47,"") | D18: =IFERROR('BB2 12-05-26'!AX48,"") | E18: =IF(C18="","",C18) | F18: =IF(D18="","",D18)
A19: 16 | B19: Élève 16 | C19: =IFERROR('BB2 12-05-26'!BA47,"") | D19: =IFERROR('BB2 12-05-26'!BA48,"") | E19: =IF(C19="","",C19) | F19: =IF(D19="","",D19)
A20: 17 | B20: Élève 17 | C20: =IFERROR('BB2 12-05-26'!BD47,"") | D20: =IFERROR('BB2 12-05-26'!BD48,"") | E20: =IF(C20="","",C20) | F20: =IF(D20="","",D20)
A21: 18 | B21: Élève 18 | C21: =IFERROR('BB2 12-05-26'!BG47,"") | D21: =IFERROR('BB2 12-05-26'!BG48,"") | E21: =IF(C21="","",C21) | F21: =IF(D21="","",D21)
A22: 19 | B22: Élève 19 | C22: =IFERROR('BB2 12-05-26'!BJ47,"") | D22: =IFERROR('BB2 12-05-26'!BJ48,"") | E22: =IF(C22="","",C22) | F22: =IF(D22="","",D22)
A23: 20 | B23: Élève 20 | C23: =IFERROR('BB2 12-05-26'!BM47,"") | D23: =IFERROR('BB2 12-05-26'!BM48,"") | E23: =IF(C23="","",C23) | F23: =IF(D23="","",D23)
A24: 21 | B24: Élève 21 | C24: =IFERROR('BB2 12-05-26'!BP47,"") | D24: =IFERROR('BB2 12-05-26'!BP48,"") | E24: =IF(C24="","",C24) | F24: =IF(D24="","",D24)
A25: 22 | B25: Élève 22 | C25: =IFERROR('BB2 12-05-26'!BS47,"") | D25: =IFERROR('BB2 12-05-26'!BS48,"") | E25: =IF(C25="","",C25) | F25: =IF(D25="","",D25)
A26: 23 | B26: Élève 23 | C26: =IFERROR('BB2 12-05-26'!BV47,"") | D26: =IFERROR('BB2 12-05-26'!BV48,"") | E26: =IF(C26="","",C26) | F26: =IF(D26="","",D26)
A27: 24 | B27: Élève 24 | C27: =IFERROR('BB2 12-05-26'!BY47,"") | D27: =IFERROR('BB2 12-05-26'!BY48,"") | E27: =IF(C27="","",C27) | F27: =IF(D27="","",D27)
A28: 25 | C28: =IFERROR('BB2 12-05-26'!CB47,"") | D28: =IFERROR('BB2 12-05-26'!CB48,"") | E28: =IF(C28="","",C28) | F28: =IF(D28="","",D28)
A29: 26 | C29: =IFERROR('BB2 12-05-26'!CE47,"") | D29: =IFERROR('BB2 12-05-26'!CE48,"") | E29: =IF(C29="","",C29) | F29: =IF(D29="","",D29)
A30: 27 | C30: =IFERROR('BB2 12-05-26'!CH47,"") | D30: =IFERROR('BB2 12-05-26'!CH48,"") | E30: =IF(C30="","",C30) | F30: =IF(D30="","",D30)
A31: 28 | C31: =IFERROR('BB2 12-05-26'!CK47,"") | D31: =IFERROR('BB2 12-05-26'!CK48,"") | E31: =IF(C31="","",C31) | F31: =IF(D31="","",D31)
A32: 29 | C32: =IFERROR('BB2 12-05-26'!CN47,"") | D32: =IFERROR('BB2 12-05-26'!CN48,"") | E32: =IF(C32="","",C32) | F32: =IF(D32="","",D32)
A33: 30 | C33: =IFERROR('BB2 12-05-26'!CQ47,"") | D33: =IFERROR('BB2 12-05-26'!CQ48,"") | E33: =IF(C33="","",C33) | F33: =IF(D33="","",D33)
B35: Moyenne classe | C35: =IFERROR(AVERAGE(C4:C33),"") | D35: =IFERROR(AVERAGE(D4:D33),"")

Sheet BB2 12-05-26
A1: BAC BLANC N°2 — 12-05-2026 — STI2D 2I2D — Site AQUALYON
A2: Analyse des performances de la station de méthanisation de la Feyssine — Partie commune (12 pts)
A3: N° | B3: Partie | C3: Question | D3: Type | E3: Critère / attendu | F3: Poids | G3: =IFERROR(IF(Élèves!B4="","E1",Élèves!B4),"E1") | J3: =IFERROR(IF(Élèves!B5="","E2",Élèves!B5),"E2") | M3: =IFERROR(IF(Élèves!B6="","E3",Élèves!B6),"E3") | P3: =IFERROR(IF(Élèves!B7="","E4",Élèves!B7),"E4") | S3: =IFERROR(IF(Élèves!B8="","E5",Élèves!B8),"E5") | V3: =IFERROR(IF(Élèves!B9="","E6",Élèves!B9),"E6") | Y3: =IFERROR(IF(Élèves!B10="","E7",Élèves!B10),"E7") | AB3: =IFERROR(IF(Élèves!B11="","E8",Élèves!B11),"E8") | AE3: =IFERROR(IF(Élèves!B12="","E9",Élèves!B12),"E9") | AH3: =IFERROR(IF(Élèves!B13="","E10",Élèves!B13),"E10") | AK3: =IFERROR(IF(Élèves!B14="","E11",Élèves!B14),"E11") | AN3: =IFERROR(IF(Élèves!B15="","E12",Élèves!B15),"E12") | AQ3: =IFERROR(IF(Élèves!B16="","E13",Élèves!B16),"E13") | AT3: =IFERROR(IF(Élèves!B17="","E14",Élèves!B17),"E14") | AW3: =IFERROR(IF(Élèves!B18="","E15",Élèves!B18),"E15") | AZ3: =IFERROR(IF(Élèves!B19="","E16",Élèves!B19),"E16") | BC3: =IFERROR(IF(Élèves!B20="","E17",Élèves!B20),"E17") | BF3: =IFERROR(IF(Élèves!B21="","E18",Élèves!B21),"E18") | BI3: =IFERROR(IF(Élèves!B22="","E19",Élèves!B22),"E19") | BL3: =IFERROR(IF(Élèves!B23="","E20",Élèves!B23),"E20") | BO3: =IFERROR(IF(Élèves!B24="","E21",Élèves!B24),"E21") | BR3: =IFERROR(IF(Élèves!B25="","E22",Élèves!B25),"E22") | BU3: =IFERROR(IF(Élèves!B26="","E23",Élèves!B26),"E23") | BX3: =IFERROR(IF(Élèves!B27="","E24",Élèves!B27),"E24") | CA3: =IFERROR(IF(Élèves!B28="","E25",Élèves!B28),"E25") | CD3: =IFERROR(IF(Élèves!B29="","E26",Élèves!B29),"E26") | CG3: =IFERROR(IF(Élèves!B30="","E27",Élèves!B30),"E27") | CJ3: =IFERROR(IF(Élèves!B31="","E28",Élèves!B31),"E28") | CM3: =IFERROR(IF(Élèves!B32="","E29",Élèves!B32),"E29") | CP3: =IFERROR(IF(Élèves!B33="","E30",Élèves!B33),"E30")
G4: Saisie | H4: Note | I4: ⚠ | J4: Saisie | K4: Note | L4: ⚠ | M4: Saisie | N4: Note | O4: ⚠ | P4: Saisie | Q4: Note | R4: ⚠ | S4: Saisie | T4: Note | U4: ⚠ | V4: Saisie | W4: Note | X4: ⚠ | Y4: Saisie | Z4: Note | AA4: ⚠ | AB4: Saisie | AC4: Note | AD4: ⚠ | AE4: Saisie | AF4: Note | AG4: ⚠ | AH4: Saisie | AI4: Note | AJ4: ⚠ | AK4: Saisie | AL4: Note | AM4: ⚠ | AN4: Saisie | AO4: Note | AP4: ⚠ | AQ4: Saisie | AR4: Note | AS4: ⚠ | AT4: Saisie | AU4: Note | AV4: ⚠ | AW4: Saisie | AX4: Note | AY4: ⚠ | AZ4: Saisie | BA4: Note | BB4: ⚠ | BC4: Saisie | BD4: Note | BE4: ⚠ | BF4: Saisie | BG4: Note | BH4: ⚠ | BI4: Saisie | BJ4: Note | BK4: ⚠ | BL4: Saisie | BM4: Note | BN4: ⚠ | BO4: Saisie | BP4: Note | BQ4: ⚠ | BR4: Saisie | BS4: Note | BT4: ⚠ | BU4: Saisie | BV4: Note | BW4: ⚠ | BX4: Saisie | BY4: Note | BZ4: ⚠ | CA4: Saisie | CB4: Note | CC4: ⚠ | CD4: Saisie | CE4: Note | CF4: ⚠ | CG4: Saisie | CH4: Note | CI4: ⚠ | CJ4: Saisie | CK4: Note | CL4: ⚠ | CM4: Saisie | CN4: Note | CO4: ⚠ | CP4: Saisie | CQ4: Note | CR4: ⚠
B5: P1 | D5: Partie | E5: Comment la station de la Feyssine permet-elle de répondre aux besoins de la métropole ? | F5: 0.2 | H5: =IFERROR(SUM(H6:H12)/(SUMPRODUCT(($F$6:$F$12)*(G6:G12<>"")*(G6:G12<>"NE"))*$F$5),"") | K5: =IFERROR(SUM(K6:K12)/(SUMPRODUCT(($F$6:$F$12)*(J6:J12<>"")*(J6:J12<>"NE"))*$F$5),"") | N5: =IFERROR(SUM(N6:N12)/(SUMPRODUCT(($F$6:$F$12)*(M6:M12<>"")*(M6:M12<>"NE"))*$F$5),"") | Q5: =IFERROR(SUM(Q6:Q12)/(SUMPRODUCT(($F$6:$F$12)*(P6:P12<>"")*(P6:P12<>"NE"))*$F$5),"") | T5: =IFERROR(SUM(T6:T12)/(SUMPRODUCT(($F$6:$F$12)*(S6:S12<>"")*(S6:S12<>"NE"))*$F$5),"") | W5: =IFERROR(SUM(W6:W12)/(SUMPRODUCT(($F$6:$F$12)*(V6:V12<>"")*(V6:V12<>"NE"))*$F$5),"") | Z5: =IFERROR(SUM(Z6:Z12)/(SUMPRODUCT(($F$6:$F$12)*(Y6:Y12<>"")*(Y6:Y12<>"NE"))*$F$5),"") | AC5: =IFERROR(SUM(AC6:AC12)/(SUMPRODUCT(($F$6:$F$12)*(AB6:AB12<>"")*(AB6:AB12<>"NE"))*$F$5),"") | AF5: =IFERROR(SUM(AF6:AF12)/(SUMPRODUCT(($F$6:$F$12)*(AE6:AE12<>"")*(AE6:AE12<>"NE"))*$F$5),"") | AI5: =IFERROR(SUM(AI6:AI12)/(SUMPRODUCT(($F$6:$F$12)*(AH6:AH12<>"")*(AH6:AH12<>"NE"))*$F$5),"") | AL5: =IFERROR(SUM(AL6:AL12)/(SUMPRODUCT(($F$6:$F$12)*(AK6:AK12<>"")*(AK6:AK12<>"NE"))*$F$5),"") | AO5: =IFERROR(SUM(AO6:AO12)/(SUMPRODUCT(($F$6:$F$12)*(AN6:AN12<>"")*(AN6:AN12<>"NE"))*$F$5),"") | AR5: =IFERROR(SUM(AR6:AR12)/(SUMPRODUCT(($F$6:$F$12)*(AQ6:AQ12<>"")*(AQ6:AQ12<>"NE"))*$F$5),"") | AU5: =IFERROR(SUM(AU6:AU12)/(SUMPRODUCT(($F$6:$F$12)*(AT6:AT12<>"")*(AT6:AT12<>"NE"))*$F$5),"") | AX5: =IFERROR(SUM(AX6:AX12)/(SUMPRODUCT(($F$6:$F$12)*(AW6:AW12<>"")*(AW6:AW12<>"NE"))*$F$5),"") | BA5: =IFERROR(SUM(BA6:BA12)/(SUMPRODUCT(($F$6:$F$12)*(AZ6:AZ12<>"")*(AZ6:AZ12<>"NE"))*$F$5),"") | BD5: =IFERROR(SUM(BD6:BD12)/(SUMPRODUCT(($F$6:$F$12)*(BC6:BC12<>"")*(BC6:BC12<>"NE"))*$F$5),"") | BG5: =IFERROR(SUM(BG6:BG12)/(SUMPRODUCT(($F$6:$F$12)*(BF6:BF12<>"")*(BF6:BF12<>"NE"))*$F$5),"") | BJ5: =IFERROR(SUM(BJ6:BJ12)/(SUMPRODUCT(($F$6:$F$12)*(BI6:BI12<>"")*(BI6:BI12<>"NE"))*$F$5),"") | BM5: =IFERROR(SUM(BM6:BM12)/(SUMPRODUCT(($F$6:$F$12)*(BL6:BL12<>"")*(BL6:BL12<>"NE"))*$F$5),"") | BP5: =IFERROR(SUM(BP6:BP12)/(SUMPRODUCT(($F$6:$F$12)*(BO6:BO12<>"")*(BO6:BO12<>"NE"))*$F$5),"") | BS5: =IFERROR(SUM(BS6:BS12)/(SUMPRODUCT(($F$6:$F$12)*(BR6:BR12<>"")*(BR6:BR12<>"NE"))*$F$5),"") | BV5: =IFERROR(SUM(BV6:BV12)/(SUMPRODUCT(($F$6:$F$12)*(BU6:BU12<>"")*(BU6:BU12<>"NE"))*$F$5),"") | BY5: =IFERROR(SUM(BY6:BY12)/(SUMPRODUCT(($F$6:$F$12)*(BX6:BX12<>"")*(BX6:BX12<>"NE"))*$F$5),"") | CB5: =IFERROR(SUM(CB6:CB12)/(SUMPRODUCT(($F$6:$F$12)*(CA6:CA12<>"")*(CA6:CA12<>"NE"))*$F$5),"") | CE5: =IFERROR(SUM(CE6:CE12)/(SUMPRODUCT(($F$6:$F$12)*(CD6:CD12<>"")*(CD6:CD12<>"NE"))*$F$5),"") | CH5: =IFERROR(SUM(CH6:CH12)/(SUMPRODUCT(($F$6:$F$12)*(CG6:CG12<>"")*(CG6:CG12<>"NE"))*$F$5),"") | CK5: =IFERROR(SUM(CK6:CK12)/(SUMPRODUCT(($F$6:$F$12)*(CJ6:CJ12<>"")*(CJ6:CJ12<>"NE"))*$F$5),"") | CN5: =IFERROR(SUM(CN6:CN12)/(SUMPRODUCT(($F$6:$F$12)*(CM6:CM12<>"")*(CM6:CM12<>"NE"))*$F$5),"") | CQ5: =IFERROR(SUM(CQ6:CQ12)/(SUMPRODUCT(($F$6:$F$12)*(CP6:CP12<>"")*(CP6:CP12<>"NE"))*$F$5),"")
A6: 1 | B6: P1 | C6: Q1.1 | D6: Critère | E6: La station de Saint-Fons est saturée en DBO. | F6: 0.15 | H6: =IF(G6="","",IF(G6="NE","",(IFERROR(IF(ISNUMBER(G6),G6,VALUE(G6)),0)/2)*$F6*$F$5*20)) | I6: =IF(G6="","◄",IF(G6="NE","~","")) | K6: =IF(J6="","",IF(J6="NE","",(IFERROR(IF(ISNUMBER(J6),J6,VALUE(J6)),0)/2)*$F6*$F$5*20)) | L6: =IF(J6="","◄",IF(J6="NE","~","")) | N6: =IF(M6="","",IF(M6="NE","",(IFERROR(IF(ISNUMBER(M6),M6,VALUE(M6)),0)/2)*$F6*$F$5*20)) | O6: =IF(M6="","◄",IF(M6="NE","~","")) | Q6: =IF(P6="","",IF(P6="NE","",(IFERROR(IF(ISNUMBER(P6),P6,VALUE(P6)),0)/2)*$F6*$F$5*20)) | R6: =IF(P6="","◄",IF(P6="NE","~","")) | T6: =IF(S6="","",IF(S6="NE","",(IFERROR(IF(ISNUMBER(S6),S6,VALUE(S6)),0)/2)*$F6*$F$5*20)) | U6: =IF(S6="","◄",IF(S6="NE","~","")) | W6: =IF(V6="","",IF(V6="NE","",(IFERROR(IF(ISNUMBER(V6),V6,VALUE(V6)),0)/2)*$F6*$F$5*20)) | X6: =IF(V6="","◄",IF(V6="NE","~","")) | Z6: =IF(Y6="","",IF(Y6="NE","",(IFERROR(IF(ISNUMBER(Y6),Y6,VALUE(Y6)),0)/2)*$F6*$F$5*20)) | AA6: =IF(Y6="","◄",IF(Y6="NE","~","")) | AC6: =IF(AB6="","",IF(AB6="NE","",(IFERROR(IF(ISNUMBER(AB6),AB6,VALUE(AB6)),0)/2)*$F6*$F$5*20)) | AD6: =IF(AB6="","◄",IF(AB6="NE","~","")) | AF6: =IF(AE6="","",IF(AE6="NE","",(IFERROR(IF(ISNUMBER(AE6),AE6,VALUE(AE6)),0)/2)*$F6*$F$5*20)) | AG6: =IF(AE6="","◄",IF(AE6="NE","~","")) | AI6: =IF(AH6="","",IF(AH6="NE","",(IFERROR(IF(ISNUMBER(AH6),AH6,VALUE(AH6)),0)/2)*$F6*$F$5*20)) | AJ6: =IF(AH6="","◄",IF(AH6="NE","~","")) | AL6: =IF(AK6="","",IF(AK6="NE","",(IFERROR(IF(ISNUMBER(AK6),AK6,VALUE(AK6)),0)/2)*$F6*$F$5*20)) | AM6: =IF(AK6="","◄",IF(AK6="NE","~","")) | AO6: =IF(AN6="","",IF(AN6="NE","",(IFERROR(IF(ISNUMBER(AN6),AN6,VALUE(AN6)),0)/2)*$F6*$F$5*20)) | AP6: =IF(AN6="","◄",IF(AN6="NE","~","")) | AR6: =IF(AQ6="","",IF(AQ6="NE","",(IFERROR(IF(ISNUMBER(AQ6),AQ6,VALUE(AQ6)),0)/2)*$F6*$F$5*20)) | AS6: =IF(AQ6="","◄",IF(AQ6="NE","~","")) | AU6: =IF(AT6="","",IF(AT6="NE","",(IFERROR(IF(ISNUMBER(AT6),AT6,VALUE(AT6)),0)/2)*$F6*$F$5*20)) | AV6: =IF(AT6="","◄",IF(AT6="NE","~","")) | AX6: =IF(AW6="","",IF(AW6="NE","",(IFERROR(IF(ISNUMBER(AW6),AW6,VALUE(AW6)),0)/2)*$F6*$F$5*20)) | AY6: =IF(AW6="","◄",IF(AW6="NE","~","")) | BA6: =IF(AZ6="","",IF(AZ6="NE","",(IFERROR(IF(ISNUMBER(AZ6),AZ6,VALUE(AZ6)),0)/2)*$F6*$F$5*20)) | BB6: =IF(AZ6="","◄",IF(AZ6="NE","~","")) | BD6: =IF(BC6="","",IF(BC6="NE","",(IFERROR(IF(ISNUMBER(BC6),BC6,VALUE(BC6)),0)/2)*$F6*$F$5*20)) | BE6: =IF(BC6="","◄",IF(BC6="NE","~","")) | BG6: =IF(BF6="","",IF(BF6="NE","",(IFERROR(IF(ISNUMBER(BF6),BF6,VALUE(BF6)),0)/2)*$F6*$F$5*20)) | BH6: =IF(BF6="","◄",IF(BF6="NE","~","")) | BJ6: =IF(BI6="","",IF(BI6="NE","",(IFERROR(IF(ISNUMBER(BI6),BI6,VALUE(BI6)),0)/2)*$F6*$F$5*20)) | BK6: =IF(BI6="","◄",IF(BI6="NE","~","")) | BM6: =IF(BL6="","",IF(BL6="NE","",(IFERROR(IF(ISNUMBER(BL6),BL6,VALUE(BL6)),0)/2)*$F6*$F$5*20)) | BN6: =IF(BL6="","◄",IF(BL6="NE","~","")) | BP6: =IF(BO6="","",IF(BO6="NE","",(IFERROR(IF(ISNUMBER(BO6),BO6,VALUE(BO6)),0)/2)*$F6*$F$5*20)) | BQ6: =IF(BO6="","◄",IF(BO6="NE","~","")) | BS6: =IF(BR6="","",IF(BR6="NE","",(IFERROR(IF(ISNUMBER(BR6),BR6,VALUE(BR6)),0)/2)*$F6*$F$5*20)) | BT6: =IF(BR6="","◄",IF(BR6="NE","~","")) | BV6: =IF(BU6="","",IF(BU6="NE","",(IFERROR(IF(ISNUMBER(BU6),BU6,VALUE(BU6)),0)/2)*$F6*$F$5*20)) | BW6: =IF(BU6="","◄",IF(BU6="NE","~","")) | BY6: =IF(BX6="","",IF(BX6="NE","",(IFERROR(IF(ISNUMBER(BX6),BX6,VALUE(BX6)),0)/2)*$F6*$F$5*20)) | BZ6: =IF(BX6="","◄",IF(BX6="NE","~","")) | CB6: =IF(CA6="","",IF(CA6="NE","",(IFERROR(IF(ISNUMBER(CA6),CA6,VALUE(CA6)),0)/2)*$F6*$F$5*20)) | CC6: =IF(CA6="","◄",IF(CA6="NE","~","")) | CE6: =IF(CD6="","",IF(CD6="NE","",(IFERROR(IF(ISNUMBER(CD6),CD6,VALUE(CD6)),0)/2)*$F6*$F$5*20)) | CF6: =IF(CD6="","◄",IF(CD6="NE","~","")) | CH6: =IF(CG6="","",IF(CG6="NE","",(IFERROR(IF(ISNUMBER(CG6),CG6,VALUE(CG6)),0)/2)*$F6*$F$5*20)) | CI6: =IF(CG6="","◄",IF(CG6="NE","~","")) | CK6: =IF(CJ6="","",IF(CJ6="NE","",(IFERROR(IF(ISNUMBER(CJ6),CJ6,VALUE(CJ6)),0)/2)*$F6*$F$5*20)) | CL6: =IF(CJ6="","◄",IF(CJ6="NE","~","")) | CN6: =IF(CM6="","",IF(CM6="NE","",(IFERROR(IF(ISNUMBER(CM6),CM6,VALUE(CM6)),0)/2)*$F6*$F$5*20)) | CO6: =IF(CM6="","◄",IF(CM6="NE","~","")) | CQ6: =IF(CP6="","",IF(CP6="NE","",(IFERROR(IF(ISNUMBER(CP6),CP6,VALUE(CP6)),0)/2)*$F6*$F$5*20)) | CR6: =IF(CP6="","◄",IF(CP6="NE","~",""))
A7: 2 | B7: P1 | C7: Q1.1 | D7: Critère | E7: Il faut construire une nouvelle station pour répondre à l'augmentation de population. | F7: 0.15 | H7: =IF(G7="","",IF(G7="NE","",(IFERROR(IF(ISNUMBER(G7),G7,VALUE(G7)),0)/2)*$F7*$F$5*20)) | I7: =IF(G7="","◄",IF(G7="NE","~","")) | K7: =IF(J7="","",IF(J7="NE","",(IFERROR(IF(ISNUMBER(J7),J7,VALUE(J7)),0)/2)*$F7*$F$5*20)) | L7: =IF(J7="","◄",IF(J7="NE","~","")) | N7: =IF(M7="","",IF(M7="NE","",(IFERROR(IF(ISNUMBER(M7),M7,VALUE(M7)),0)/2)*$F7*$F$5*20)) | O7: =IF(M7="","◄",IF(M7="NE","~","")) | Q7: =IF(P7="","",IF(P7="NE","",(IFERROR(IF(ISNUMBER(P7),P7,VALUE(P7)),0)/2)*$F7*$F$5*20)) | R7: =IF(P7="","◄",IF(P7="NE","~","")) | T7: =IF(S7="","",IF(S7="NE","",(IFERROR(IF(ISNUMBER(S7),S7,VALUE(S7)),0)/2)*$F7*$F$5*20)) | U7: =IF(S7="","◄",IF(S7="NE","~","")) | W7: =IF(V7="","",IF(V7="NE","",(IFERROR(IF(ISNUMBER(V7),V7,VALUE(V7)),0)/2)*$F7*$F$5*20)) | X7: =IF(V7="","◄",IF(V7="NE","~","")) | Z7: =IF(Y7="","",IF(Y7="NE","",(IFERROR(IF(ISNUMBER(Y7),Y7,VALUE(Y7)),0)/2)*$F7*$F$5*20)) | AA7: =IF(Y7="","◄",IF(Y7="NE","~","")) | AC7: =IF(AB7="","",IF(AB7="NE","",(IFERROR(IF(ISNUMBER(AB7),AB7,VALUE(AB7)),0)/2)*$F7*$F$5*20)) | AD7: =IF(AB7="","◄",IF(AB7="NE","~","")) | AF7: =IF(AE7="","",IF(AE7="NE","",(IFERROR(IF(ISNUMBER(AE7),AE7,VALUE(AE7)),0)/2)*$F7*$F$5*20)) | AG7: =IF(AE7="","◄",IF(AE7="NE","~","")) | AI7: =IF(AH7="","",IF(AH7="NE","",(IFERROR(IF(ISNUMBER(AH7),AH7,VALUE(AH7)),0)/2)*$F7*$F$5*20)) | AJ7: =IF(AH7="","◄",IF(AH7="NE","~","")) | AL7: =IF(AK7="","",IF(AK7="NE","",(IFERROR(IF(ISNUMBER(AK7),AK7,VALUE(AK7)),0)/2)*$F7*$F$5*20)) | AM7: =IF(AK7="","◄",IF(AK7="NE","~","")) | AO7: =IF(AN7="","",IF(AN7="NE","",(IFERROR(IF(ISNUMBER(AN7),AN7,VALUE(AN7)),0)/2)*$F7*$F$5*20)) | AP7: =IF(AN7="","◄",IF(AN7="NE","~","")) | AR7: =IF(AQ7="","",IF(AQ7="NE","",(IFERROR(IF(ISNUMBER(AQ7),AQ7,VALUE(AQ7)),0)/2)*$F7*$F$5*20)) | AS7: =IF(AQ7="","◄",IF(AQ7="NE","~","")) | AU7: =IF(AT7="","",IF(AT7="NE","",(IFERROR(IF(ISNUMBER(AT7),AT7,VALUE(AT7)),0)/2)*$F7*$F$5*20)) | AV7: =IF(AT7="","◄",IF(AT7="NE","~","")) | AX7: =IF(AW7="","",IF(AW7="NE","",(IFERROR(IF(ISNUMBER(AW7),AW7,VALUE(AW7)),0)/2)*$F7*$F$5*20)) | AY7: =IF(AW7="","◄",IF(AW7="NE","~","")) | BA7: =IF(AZ7="","",IF(AZ7="NE","",(IFERROR(IF(ISNUMBER(AZ7),AZ7,VALUE(AZ7)),0)/2)*$F7*$F$5*20)) | BB7: =IF(AZ7="","◄",IF(AZ7="NE","~","")) | BD7: =IF(BC7="","",IF(BC7="NE","",(IFERROR(IF(ISNUMBER(BC7),BC7,VALUE(BC7)),0)/2)*$F7*$F$5*20)) | BE7: =IF(BC7="","◄",IF(BC7="NE","~","")) | BG7: =IF(BF7="","",IF(BF7="NE","",(IFERROR(IF(ISNUMBER(BF7),BF7,VALUE(BF7)),0)/2)*$F7*$F$5*20)) | BH7: =IF(BF7="","◄",IF(BF7="NE","~","")) | BJ7: =IF(BI7="","",IF(BI7="NE","",(IFERROR(IF(ISNUMBER(BI7),BI7,VALUE(BI7)),0)/2)*$F7*$F$5*20)) | BK7: =IF(BI7="","◄",IF(BI7="NE","~","")) | BM7: =IF(BL7="","",IF(BL7="NE","",(IFERROR(IF(ISNUMBER(BL7),BL7,VALUE(BL7)),0)/2)*$F7*$F$5*20)) | BN7: =IF(BL7="","◄",IF(BL7="NE","~","")) | BP7: =IF(BO7="","",IF(BO7="NE","",(IFERROR(IF(ISNUMBER(BO7),BO7,VALUE(BO7)),0)/2)*$F7*$F$5*20)) | BQ7: =IF(BO7="","◄",IF(BO7="NE","~","")) | BS7: =IF(BR7="","",IF(BR7="NE","",(IFERROR(IF(ISNUMBER(BR7),BR7,VALUE(BR7)),0)/2)*$F7*$F$5*20)) | BT7: =IF(BR7="","◄",IF(BR7="NE","~","")) | BV7: =IF(BU7="","",IF(BU7="NE","",(IFERROR(IF(ISNUMBER(BU7),BU7,VALUE(BU7)),0)/2)*$F7*$F$5*20)) | BW7: =IF(BU7="","◄",IF(BU7="NE","~","")) | BY7: =IF(BX7="","",IF(BX7="NE","",(IFERROR(IF(ISNUMBER(BX7),BX7,VALUE(BX7)),0)/2)*$F7*$F$5*20)) | BZ7: =IF(BX7="","◄",IF(BX7="NE","~","")) | CB7: =IF(CA7="","",IF(CA7="NE","",(IFERROR(IF(ISNUMBER(CA7),CA7,VALUE(CA7)),0)/2)*$F7*$F$5*20)) | CC7: =IF(CA7="","◄",IF(CA7="NE","~","")) | CE7: =IF(CD7="","",IF(CD7="NE","",(IFERROR(IF(ISNUMBER(CD7),CD7,VALUE(CD7)),0)/2)*$F7*$F$5*20)) | CF7: =IF(CD7="","◄",IF(CD7="NE","~","")) | CH7: =IF(CG7="","",IF(CG7="NE","",(IFERROR(IF(ISNUMBER(CG7),CG7,VALUE(CG7)),0)/2)*$F7*$F$5*20)) | CI7: =IF(CG7="","◄",IF(CG7="NE","~","")) | CK7: =IF(CJ7="","",IF(CJ7="NE","",(IFERROR(IF(ISNUMBER(CJ7),CJ7,VALUE(CJ7)),0)/2)*$F7*$F$5*20)) | CL7: =IF(CJ7="","◄",IF(CJ7="NE","~","")) | CN7: =IF(CM7="","",IF(CM7="NE","",(IFERROR(IF(ISNUMBER(CM7),CM7,VALUE(CM7)),0)/2)*$F7*$F$5*20)) | CO7: =IF(CM7="","◄",IF(CM7="NE","~","")) | CQ7: =IF(CP7="","",IF(CP7="NE","",(IFERROR(IF(ISNUMBER(CP7),CP7,VALUE(CP7)),0)/2)*$F7*$F$5*20)) | CR7: =IF(CP7="","◄",IF(CP7="NE","~",""))
A8: 3 | B8: P1 | C8: Q1.2 | D8: Critère | E8: Justification : terrain près du Rhône, près du périphérique, point altimétrique bas, entouré de parc naturel (pas d'habitation proche). | F8: 0.15 | H8: =IF(G8="","",IF(G8="NE","",(IFERROR(IF(ISNUMBER(G8),G8,VALUE(G8)),0)/2)*$F8*$F$5*20)) | I8: =IF(G8="","◄",IF(G8="NE","~","")) | K8: =IF(J8="","",IF(J8="NE","",(IFERROR(IF(ISNUMBER(J8),J8,VALUE(J8)),0)/2)*$F8*$F$5*20)) | L8: =IF(J8="","◄",IF(J8="NE","~","")) | N8: =IF(M8="","",IF(M8="NE","",(IFERROR(IF(ISNUMBER(M8),M8,VALUE(M8)),0)/2)*$F8*$F$5*20)) | O8: =IF(M8="","◄",IF(M8="NE","~","")) | Q8: =IF(P8="","",IF(P8="NE","",(IFERROR(IF(ISNUMBER(P8),P8,VALUE(P8)),0)/2)*$F8*$F$5*20)) | R8: =IF(P8="","◄",IF(P8="NE","~","")) | T8: =IF(S8="","",IF(S8="NE","",(IFERROR(IF(ISNUMBER(S8),S8,VALUE(S8)),0)/2)*$F8*$F$5*20)) | U8: =IF(S8="","◄",IF(S8="NE","~","")) | W8: =IF(V8="","",IF(V8="NE","",(IFERROR(IF(ISNUMBER(V8),V8,VALUE(V8)),0)/2)*$F8*$F$5*20)) | X8: =IF(V8="","◄",IF(V8="NE","~","")) | Z8: =IF(Y8="","",IF(Y8="NE","",(IFERROR(IF(ISNUMBER(Y8),Y8,VALUE(Y8)),0)/2)*$F8*$F$5*20)) | AA8: =IF(Y8="","◄",IF(Y8="NE","~","")) | AC8: =IF(AB8="","",IF(AB8="NE","",(IFERROR(IF(ISNUMBER(AB8),AB8,VALUE(AB8)),0)/2)*$F8*$F$5*20)) | AD8: =IF(AB8="","◄",IF(AB8="NE","~","")) | AF8: =IF(AE8="","",IF(AE8="NE","",(IFERROR(IF(ISNUMBER(AE8),AE8,VALUE(AE8)),0)/2)*$F8*$F$5*20)) | AG8: =IF(AE8="","◄",IF(AE8="NE","~","")) | AI8: =IF(AH8="","",IF(AH8="NE","",(IFERROR(IF(ISNUMBER(AH8),AH8,VALUE(AH8)),0)/2)*$F8*$F$5*20)) | AJ8: =IF(AH8="","◄",IF(AH8="NE","~","")) | AL8: =IF(AK8="","",IF(AK8="NE","",(IFERROR(IF(ISNUMBER(AK8),AK8,VALUE(AK8)),0)/2)*$F8*$F$5*20)) | AM8: =IF(AK8="","◄",IF(AK8="NE","~","")) | AO8: =IF(AN8="","",IF(AN8="NE","",(IFERROR(IF(ISNUMBER(AN8),AN8,VALUE(AN8)),0)/2)*$F8*$F$5*20)) | AP8: =IF(AN8="","◄",IF(AN8="NE","~","")) | AR8: =IF(AQ8="","",IF(AQ8="NE","",(IFERROR(IF(ISNUMBER(AQ8),AQ8,VALUE(AQ8)),0)/2)*$F8*$F$5*20)) | AS8: =IF(AQ8="","◄",IF(AQ8="NE","~","")) | AU8: =IF(AT8="","",IF(AT8="NE","",(IFERROR(IF(ISNUMBER(AT8),AT8,VALUE(AT8)),0)/2)*$F8*$F$5*20)) | AV8: =IF(AT8="","◄",IF(AT8="NE","~","")) | AX8: =IF(AW8="","",IF(AW8="NE","",(IFERROR(IF(ISNUMBER(AW8),AW8,VALUE(AW8)),0)/2)*$F8*$F$5*20)) | AY8: =IF(AW8="","◄",IF(AW8="NE","~","")) | BA8: =IF(AZ8="","",IF(AZ8="NE","",(IFERROR(IF(ISNUMBER(AZ8),AZ8,VALUE(AZ8)),0)/2)*$F8*$F$5*20)) | BB8: =IF(AZ8="","◄",IF(AZ8="NE","~","")) | BD8: =IF(BC8="","",IF(BC8="NE","",(IFERROR(IF(ISNUMBER(BC8),BC8,VALUE(BC8)),0)/2)*$F8*$F$5*20)) | BE8: =IF(BC8="","◄",IF(BC8="NE","~","")) | BG8: =IF(BF8="","",IF(BF8="NE","",(IFERROR(IF(ISNUMBER(BF8),BF8,VALUE(BF8)),0)/2)*$F8*$F$5*20)) | BH8: =IF(BF8="","◄",IF(BF8="NE","~","")) | BJ8: =IF(BI8="","",IF(BI8="NE","",(IFERROR(IF(ISNUMBER(BI8),BI8,VALUE(BI8)),0)/2)*$F8*$F$5*20)) | BK8: =IF(BI8="","◄",IF(BI8="NE","~","")) | BM8: =IF(BL8="","",IF(BL8="NE","",(IFERROR(IF(ISNUMBER(BL8),BL8,VALUE(BL8)),0)/2)*$F8*$F$5*20)) | BN8: =IF(BL8="","◄",IF(BL8="NE","~","")) | BP8: =IF(BO8="","",IF(BO8="NE","",(IFERROR(IF(ISNUMBER(BO8),BO8,VALUE(BO8)),0)/2)*$F8*$F$5*20)) | BQ8: =IF(BO8="","◄",IF(BO8="NE","~","")) | BS8: =IF(BR8="","",IF(BR8="NE","",(IFERROR(IF(ISNUMBER(BR8),BR8,VALUE(BR8)),0)/2)*$F8*$F$5*20)) | BT8: =IF(BR8="","◄",IF(BR8="NE","~","")) | BV8: =IF(BU8="","",IF(BU8="NE","",(IFERROR(IF(ISNUMBER(BU8),BU8,VALUE(BU8)),0)/2)*$F8*$F$5*20)) | BW8: =IF(BU8="","◄",IF(BU8="NE","~","")) | BY8: =IF(BX8="","",IF(BX8="NE","",(IFERROR(IF(ISNUMBER(BX8),BX8,VALUE(BX8)),0)/2)*$F8*$F$5*20)) | BZ8: =IF(BX8="","◄",IF(BX8="NE","~","")) | CB8: =IF(CA8="","",IF(CA8="NE","",(IFERROR(IF(ISNUMBER(CA8),CA8,VALUE(CA8)),0)/2)*$F8*$F$5*20)) | CC8: =IF(CA8="","◄",IF(CA8="NE","~","")) | CE8: =IF(CD8="","",IF(CD8="NE","",(IFERROR(IF(ISNUMBER(CD8),CD8,VALUE(CD8)),0)/2)*$F8*$F$5*20)) | CF8: =IF(CD8="","◄",IF(CD8="NE","~","")) | CH8: =IF(CG8="","",IF(CG8="NE","",(IFERROR(IF(ISNUMBER(CG8),CG8,VALUE(CG8)),0)/2)*$F8*$F$5*20)) | CI8: =IF(CG8="","◄",IF(CG8="NE","~","")) | CK8: =IF(CJ8="","",IF(CJ8="NE","",(IFERROR(IF(ISNUMBER(CJ8),CJ8,VALUE(CJ8)),0)/2)*$F8*$F$5*20)) | CL8: =IF(CJ8="","◄",IF(CJ8="NE","~","")) | CN8: =IF(CM8="","",IF(CM8="NE","",(IFERROR(IF(ISNUMBER(CM8),CM8,VALUE(CM8)),0)/2)*$F8*$F$5*20)) | CO8: =IF(CM8="","◄",IF(CM8="NE","~","")) | CQ8: =IF(CP8="","",IF(CP8="NE","",(IFERROR(IF(ISNUMBER(CP8),CP8,VALUE(CP8)),0)/2)*$F8*$F$5*20)) | CR8: =IF(CP8="","◄",IF(CP8="NE","~",""))
A9: 4 | B9: P1 | C9: Q1.3 | D9: Critère | E9: Surface lit roseaux = 10 m²/EqHab × 300 000 = 3 000 000 m² (300 ha). | F9: 0.15 | H9: =IF(G9="","",IF(G9="NE","",(IFERROR(IF(ISNUMBER(G9),G9,VALUE(G9)),0)/2)*$F9*$F$5*20)) | I9: =IF(G9="","◄",IF(G9="NE","~","")) | K9: =IF(J9="","",IF(J9="NE","",(IFERROR(IF(ISNUMBER(J9),J9,VALUE(J9)),0)/2)*$F9*$F$5*20)) | L9: =IF(J9="","◄",IF(J9="NE","~","")) | N9: =IF(M9="","",IF(M9="NE","",(IFERROR(IF(ISNUMBER(M9),M9,VALUE(M9)),0)/2)*$F9*$F$5*20)) | O9: =IF(M9="","◄",IF(M9="NE","~","")) | Q9: =IF(P9="","",IF(P9="NE","",(IFERROR(IF(ISNUMBER(P9),P9,VALUE(P9)),0)/2)*$F9*$F$5*20)) | R9: =IF(P9="","◄",IF(P9="NE","~","")) | T9: =IF(S9="","",IF(S9="NE","",(IFERROR(IF(ISNUMBER(S9),S9,VALUE(S9)),0)/2)*$F9*$F$5*20)) | U9: =IF(S9="","◄",IF(S9="NE","~","")) | W9: =IF(V9="","",IF(V9="NE","",(IFERROR(IF(ISNUMBER(V9),V9,VALUE(V9)),0)/2)*$F9*$F$5*20)) | X9: =IF(V9="","◄",IF(V9="NE","~","")) | Z9: =IF(Y9="","",IF(Y9="NE","",(IFERROR(IF(ISNUMBER(Y9),Y9,VALUE(Y9)),0)/2)*$F9*$F$5*20)) | AA9: =IF(Y9="","◄",IF(Y9="NE","~","")) | AC9: =IF(AB9="","",IF(AB9="NE","",(IFERROR(IF(ISNUMBER(AB9),AB9,VALUE(AB9)),0)/2)*$F9*$F$5*20)) | AD9: =IF(AB9="","◄",IF(AB9="NE","~","")) | AF9: =IF(AE9="","",IF(AE9="NE","",(IFERROR(IF(ISNUMBER(AE9),AE9,VALUE(AE9)),0)/2)*$F9*$F$5*20)) | AG9: =IF(AE9="","◄",IF(AE9="NE","~","")) | AI9: =IF(AH9="","",IF(AH9="NE","",(IFERROR(IF(ISNUMBER(AH9),AH9,VALUE(AH9)),0)/2)*$F9*$F$5*20)) | AJ9: =IF(AH9="","◄",IF(AH9="NE","~","")) | AL9: =IF(AK9="","",IF(AK9="NE","",(IFERROR(IF(ISNUMBER(AK9),AK9,VALUE(AK9)),0)/2)*$F9*$F$5*20)) | AM9: =IF(AK9="","◄",IF(AK9="NE","~","")) | AO9: =IF(AN9="","",IF(AN9="NE","",(IFERROR(IF(ISNUMBER(AN9),AN9,VALUE(AN9)),0)/2)*$F9*$F$5*20)) | AP9: =IF(AN9="","◄",IF(AN9="NE","~","")) | AR9: =IF(AQ9="","",IF(AQ9="NE","",(IFERROR(IF(ISNUMBER(AQ9),AQ9,VALUE(AQ9)),0)/2)*$F9*$F$5*20)) | AS9: =IF(AQ9="","◄",IF(AQ9="NE","~","")) | AU9: =IF(AT9="","",IF(AT9="NE","",(IFERROR(IF(ISNUMBER(AT9),AT9,VALUE(AT9)),0)/2)*$F9*$F$5*20)) | AV9: =IF(AT9="","◄",IF(AT9="NE","~","")) | AX9: =IF(AW9="","",IF(AW9="NE","",(IFERROR(IF(ISNUMBER(AW9),AW9,VALUE(AW9)),0)/2)*$F9*$F$5*20)) | AY9: =IF(AW9="","◄",IF(AW9="NE","~","")) | BA9: =IF(AZ9="","",IF(AZ9="NE","",(IFERROR(IF(ISNUMBER(AZ9),AZ9,VALUE(AZ9)),0)/2)*$F9*$F$5*20)) | BB9: =IF(AZ9="","◄",IF(AZ9="NE","~","")) | BD9: =IF(BC9="","",IF(BC9="NE","",(IFERROR(IF(ISNUMBER(BC9),BC9,VALUE(BC9)),0)/2)*$F9*$F$5*20)) | BE9: =IF(BC9="","◄",IF(BC9="NE","~","")) | BG9: =IF(BF9="","",IF(BF9="NE","",(IFERROR(IF(ISNUMBER(BF9),BF9,VALUE(BF9)),0)/2)*$F9*$F$5*20)) | BH9: =IF(BF9="","◄",IF(BF9="NE","~","")) | BJ9: =IF(BI9="","",IF(BI9="NE","",(IFERROR(IF(ISNUMBER(BI9),BI9,VALUE(BI9)),0)/2)*$F9*$F$5*20)) | BK9: =IF(BI9="","◄",IF(BI9="NE","~","")) | BM9: =IF(BL9="","",IF(BL9="NE","",(IFERROR(IF(ISNUMBER(BL9),BL9,VALUE(BL9)),0)/2)*$F9*$F$5*20)) | BN9: =IF(BL9="","◄",IF(BL9="NE","~","")) | BP9: =IF(BO9="","",IF(BO9="NE","",(IFERROR(IF(ISNUMBER(BO9),BO9,VALUE(BO9)),0)/2)*$F9*$F$5*20)) | BQ9: =IF(BO9="","◄",IF(BO9="NE","~","")) | BS9: =IF(BR9="","",IF(BR9="NE","",(IFERROR(IF(ISNUMBER(BR9),BR9,VALUE(BR9)),0)/2)*$F9*$F$5*20)) | BT9: =IF(BR9="","◄",IF(BR9="NE","~","")) | BV9: =IF(BU9="","",IF(BU9="NE","",(IFERROR(IF(ISNUMBER(BU9),BU9,VALUE(BU9)),0)/2)*$F9*$F$5*20)) | BW9: =IF(BU9="","◄",IF(BU9="NE","~","")) | BY9: =IF(BX9="","",IF(BX9="NE","",(IFERROR(IF(ISNUMBER(BX9),BX9,VALUE(BX9)),0)/2)*$F9*$F$5*20)) | BZ9: =IF(BX9="","◄",IF(BX9="NE","~","")) | CB9: =IF(CA9="","",IF(CA9="NE","",(IFERROR(IF(ISNUMBER(CA9),CA9,VALUE(CA9)),0)/2)*$F9*$F$5*20)) | CC9: =IF(CA9="","◄",IF(CA9="NE","~","")) | CE9: =IF(CD9="","",IF(CD9="NE","",(IFERROR(IF(ISNUMBER(CD9),CD9,VALUE(CD9)),0)/2)*$F9*$F$5*20)) | CF9: =IF(CD9="","◄",IF(CD9="NE","~","")) | CH9: =IF(CG9="","",IF(CG9="NE","",(IFERROR(IF(ISNUMBER(CG9),CG9,VALUE(CG9)),0)/2)*$F9*$F$5*20)) | CI9: =IF(CG9="","◄",IF(CG9="NE","~","")) | CK9: =IF(CJ9="","",IF(CJ9="NE","",(IFERROR(IF(ISNUMBER(CJ9),CJ9,VALUE(CJ9)),0)/2)*$F9*$F$5*20)) | CL9: =IF(CJ9="","◄",IF(CJ9="NE","~","")) | CN9: =IF(CM9="","",IF(CM9="NE","",(IFERROR(IF(ISNUMBER(CM9),CM9,VALUE(CM9)),0)/2)*$F9*$F$5*20)) | CO9: =IF(CM9="","◄",IF(CM9="NE","~","")) | CQ9: =IF(CP9="","",IF(CP9="NE","",(IFERROR(IF(ISNUMBER(CP9),CP9,VALUE(CP9)),0)/2)*$F9*$F$5*20)) | CR9: =IF(CP9="","◄",IF(CP9="NE","~",""))
A10: 5 | B10: P1 | C10: Q1.3 | D10: Critère | E10: Conso énergie Boue Activée = 3,2 kWh/kgDBO5 × 17 100 = 54 720 kWh. | F10: 0.15 | H10: =IF(G10="","",IF(G10="NE","",(IFERROR(IF(ISNUMBER(G10),G10,VALUE(G10)),0)/2)*$F10*$F$5*20)) | I10: =IF(G10="","◄",IF(G10="NE","~","")) | K10: =IF(J10="","",IF(J10="NE","",(IFERROR(IF(ISNUMBER(J10),J10,VALUE(J10)),0)/2)*$F10*$F$5*20)) | L10: =IF(J10="","◄",IF(J10="NE","~","")) | N10: =IF(M10="","",IF(M10="NE","",(IFERROR(IF(ISNUMBER(M10),M10,VALUE(M10)),0)/2)*$F10*$F$5*20)) | O10: =IF(M10="","◄",IF(M10="NE","~","")) | Q10: =IF(P10="","",IF(P10="NE","",(IFERROR(IF(ISNUMBER(P10),P10,VALUE(P10)),0)/2)*$F10*$F$5*20)) | R10: =IF(P10="","◄",IF(P10="NE","~","")) | T10: =IF(S10="","",IF(S10="NE","",(IFERROR(IF(ISNUMBER(S10),S10,VALUE(S10)),0)/2)*$F10*$F$5*20)) | U10: =IF(S10="","◄",IF(S10="NE","~","")) | W10: =IF(V10="","",IF(V10="NE","",(IFERROR(IF(ISNUMBER(V10),V10,VALUE(V10)),0)/2)*$F10*$F$5*20)) | X10: =IF(V10="","◄",IF(V10="NE","~","")) | Z10: =IF(Y10="","",IF(Y10="NE","",(IFERROR(IF(ISNUMBER(Y10),Y10,VALUE(Y10)),0)/2)*$F10*$F$5*20)) | AA10: =IF(Y10="","◄",IF(Y10="NE","~","")) | AC10: =IF(AB10="","",IF(AB10="NE","",(IFERROR(IF(ISNUMBER(AB10),AB10,VALUE(AB10)),0)/2)*$F10*$F$5*20)) | AD10: =IF(AB10="","◄",IF(AB10="NE","~","")) | AF10: =IF(AE10="","",IF(AE10="NE","",(IFERROR(IF(ISNUMBER(AE10),AE10,VALUE(AE10)),0)/2)*$F10*$F$5*20)) | AG10: =IF(AE10="","◄",IF(AE10="NE","~","")) | AI10: =IF(AH10="","",IF(AH10="NE","",(IFERROR(IF(ISNUMBER(AH10),AH10,VALUE(AH10)),0)/2)*$F10*$F$5*20)) | AJ10: =IF(AH10="","◄",IF(AH10="NE","~","")) | AL10: =IF(AK10="","",IF(AK10="NE","",(IFERROR(IF(ISNUMBER(AK10),AK10,VALUE(AK10)),0)/2)*$F10*$F$5*20)) | AM10: =IF(AK10="","◄",IF(AK10="NE","~","")) | AO10: =IF(AN10="","",IF(AN10="NE","",(IFERROR(IF(ISNUMBER(AN10),AN10,VALUE(AN10)),0)/2)*$F10*$F$5*20)) | AP10: =IF(AN10="","◄",IF(AN10="NE","~","")) | AR10: =IF(AQ10="","",IF(AQ10="NE","",(IFERROR(IF(ISNUMBER(AQ10),AQ10,VALUE(AQ10)),0)/2)*$F10*$F$5*20)) | AS10: =IF(AQ10="","◄",IF(AQ10="NE","~","")) | AU10: =IF(AT10="","",IF(AT10="NE","",(IFERROR(IF(ISNUMBER(AT10),AT10,VALUE(AT10)),0)/2)*$F10*$F$5*20)) | AV10: =IF(AT10="","◄",IF(AT10="NE","~","")) | AX10: =IF(AW10="","",IF(AW10="NE","",(IFERROR(IF(ISNUMBER(AW10),AW10,VALUE(AW10)),0)/2)*$F10*$F$5*20)) | AY10: =IF(AW10="","◄",IF(AW10="NE","~","")) | BA10: =IF(AZ10="","",IF(AZ10="NE","",(IFERROR(IF(ISNUMBER(AZ10),AZ10,VALUE(AZ10)),0)/2)*$F10*$F$5*20)) | BB10: =IF(AZ10="","◄",IF(AZ10="NE","~","")) | BD10: =IF(BC10="","",IF(BC10="NE","",(IFERROR(IF(ISNUMBER(BC10),BC10,VALUE(BC10)),0)/2)*$F10*$F$5*20)) | BE10: =IF(BC10="","◄",IF(BC10="NE","~","")) | BG10: =IF(BF10="","",IF(BF10="NE","",(IFERROR(IF(ISNUMBER(BF10),BF10,VALUE(BF10)),0)/2)*$F10*$F$5*20)) | BH10: =IF(BF10="","◄",IF(BF10="NE","~","")) | BJ10: =IF(BI10="","",IF(BI10="NE","",(IFERROR(IF(ISNUMBER(BI10),BI10,VALUE(BI10)),0)/2)*$F10*$F$5*20)) | BK10: =IF(BI10="","◄",IF(BI10="NE","~","")) | BM10: =IF(BL10="","",IF(BL10="NE","",(IFERROR(IF(ISNUMBER(BL10),BL10,VALUE(BL10)),0)/2)*$F10*$F$5*20)) | BN10: =IF(BL10="","◄",IF(BL10="NE","~","")) | BP10: =IF(BO10="","",IF(BO10="NE","",(IFERROR(IF(ISNUMBER(BO10),BO10,VALUE(BO10)),0)/2)*$F10*$F$5*20)) | BQ10: =IF(BO10="","◄",IF(BO10="NE","~","")) | BS10: =IF(BR10="","",IF(BR10="NE","",(IFERROR(IF(ISNUMBER(BR10),BR10,VALUE(BR10)),0)/2)*$F10*$F$5*20)) | BT10: =IF(BR10="","◄",IF(BR10="NE","~","")) | BV10: =IF(BU10="","",IF(BU10="NE","",(IFERROR(IF(ISNUMBER(BU10),BU10,VALUE(BU10)),0)/2)*$F10*$F$5*20)) | BW10: =IF(BU10="","◄",IF(BU10="NE","~","")) | BY10: =IF(BX10="","",IF(BX10="NE","",(IFERROR(IF(ISNUMBER(BX10),BX10,VALUE(BX10)),0)/2)*$F10*$F$5*20)) | BZ10: =IF(BX10="","◄",IF(BX10="NE","~","")) | CB10: =IF(CA10="","",IF(CA10="NE","",(IFERROR(IF(ISNUMBER(CA10),CA10,VALUE(CA10)),0)/2)*$F10*$F$5*20)) | CC10: =IF(CA10="","◄",IF(CA10="NE","~","")) | CE10: =IF(CD10="","",IF(CD10="NE","",(IFERROR(IF(ISNUMBER(CD10),CD10,VALUE(CD10)),0)/2)*$F10*$F$5*20)) | CF10: =IF(CD10="","◄",IF(CD10="NE","~","")) | CH10: =IF(CG10="","",IF(CG10="NE","",(IFERROR(IF(ISNUMBER(CG10),CG10,VALUE(CG10)),0)/2)*$F10*$F$5*20)) | CI10: =IF(CG10="","◄",IF(CG10="NE","~","")) | CK10: =IF(CJ10="","",IF(CJ10="NE","",(IFERROR(IF(ISNUMBER(CJ10),CJ10,VALUE(CJ10)),0)/2)*$F10*$F$5*20)) | CL10: =IF(CJ10="","◄",IF(CJ10="NE","~","")) | CN10: =IF(CM10="","",IF(CM10="NE","",(IFERROR(IF(ISNUMBER(CM10),CM10,VALUE(CM10)),0)/2)*$F10*$F$5*20)) | CO10: =IF(CM10="","◄",IF(CM10="NE","~","")) | CQ10: =IF(CP10="","",IF(CP10="NE","",(IFERROR(IF(ISNUMBER(CP10),CP10,VALUE(CP10)),0)/2)*$F10*$F$5*20)) | CR10: =IF(CP10="","◄",IF(CP10="NE","~",""))
A11: 6 | B11: P1 | C11: Q1.3 | D11: Critère | E11: Coût biofiltre = 2 142 €/EqHab × 300 000 = 642,6 M€. | F11: 0.15 | H11: =IF(G11="","",IF(G11="NE","",(IFERROR(IF(ISNUMBER(G11),G11,VALUE(G11)),0)/2)*$F11*$F$5*20)) | I11: =IF(G11="","◄",IF(G11="NE","~","")) | K11: =IF(J11="","",IF(J11="NE","",(IFERROR(IF(ISNUMBER(J11),J11,VALUE(J11)),0)/2)*$F11*$F$5*20)) | L11: =IF(J11="","◄",IF(J11="NE","~","")) | N11: =IF(M11="","",IF(M11="NE","",(IFERROR(IF(ISNUMBER(M11),M11,VALUE(M11)),0)/2)*$F11*$F$5*20)) | O11: =IF(M11="","◄",IF(M11="NE","~","")) | Q11: =IF(P11="","",IF(P11="NE","",(IFERROR(IF(ISNUMBER(P11),P11,VALUE(P11)),0)/2)*$F11*$F$5*20)) | R11: =IF(P11="","◄",IF(P11="NE","~","")) | T11: =IF(S11="","",IF(S11="NE","",(IFERROR(IF(ISNUMBER(S11),S11,VALUE(S11)),0)/2)*$F11*$F$5*20)) | U11: =IF(S11="","◄",IF(S11="NE","~","")) | W11: =IF(V11="","",IF(V11="NE","",(IFERROR(IF(ISNUMBER(V11),V11,VALUE(V11)),0)/2)*$F11*$F$5*20)) | X11: =IF(V11="","◄",IF(V11="NE","~","")) | Z11: =IF(Y11="","",IF(Y11="NE","",(IFERROR(IF(ISNUMBER(Y11),Y11,VALUE(Y11)),0)/2)*$F11*$F$5*20)) | AA11: =IF(Y11="","◄",IF(Y11="NE","~","")) | AC11: =IF(AB11="","",IF(AB11="NE","",(IFERROR(IF(ISNUMBER(AB11),AB11,VALUE(AB11)),0)/2)*$F11*$F$5*20)) | AD11: =IF(AB11="","◄",IF(AB11="NE","~","")) | AF11: =IF(AE11="","",IF(AE11="NE","",(IFERROR(IF(ISNUMBER(AE11),AE11,VALUE(AE11)),0)/2)*$F11*$F$5*20)) | AG11: =IF(AE11="","◄",IF(AE11="NE","~","")) | AI11: =IF(AH11="","",IF(AH11="NE","",(IFERROR(IF(ISNUMBER(AH11),AH11,VALUE(AH11)),0)/2)*$F11*$F$5*20)) | AJ11: =IF(AH11="","◄",IF(AH11="NE","~","")) | AL11: =IF(AK11="","",IF(AK11="NE","",(IFERROR(IF(ISNUMBER(AK11),AK11,VALUE(AK11)),0)/2)*$F11*$F$5*20)) | AM11: =IF(AK11="","◄",IF(AK11="NE","~","")) | AO11: =IF(AN11="","",IF(AN11="NE","",(IFERROR(IF(ISNUMBER(AN11),AN11,VALUE(AN11)),0)/2)*$F11*$F$5*20)) | AP11: =IF(AN11="","◄",IF(AN11="NE","~","")) | AR11: =IF(AQ11="","",IF(AQ11="NE","",(IFERROR(IF(ISNUMBER(AQ11),AQ11,VALUE(AQ11)),0)/2)*$F11*$F$5*20)) | AS11: =IF(AQ11="","◄",IF(AQ11="NE","~","")) | AU11: =IF(AT11="","",IF(AT11="NE","",(IFERROR(IF(ISNUMBER(AT11),AT11,VALUE(AT11)),0)/2)*$F11*$F$5*20)) | AV11: =IF(AT11="","◄",IF(AT11="NE","~","")) | AX11: =IF(AW11="","",IF(AW11="NE","",(IFERROR(IF(ISNUMBER(AW11),AW11,VALUE(AW11)),0)/2)*$F11*$F$5*20)) | AY11: =IF(AW11="","◄",IF(AW11="NE","~","")) | BA11: =IF(AZ11="","",IF(AZ11="NE","",(IFERROR(IF(ISNUMBER(AZ11),AZ11,VALUE(AZ11)),0)/2)*$F11*$F$5*20)) | BB11: =IF(AZ11="","◄",IF(AZ11="NE","~","")) | BD11: =IF(BC11="","",IF(BC11="NE","",(IFERROR(IF(ISNUMBER(BC11),BC11,VALUE(BC11)),0)/2)*$F11*$F$5*20)) | BE11: =IF(BC11="","◄",IF(BC11="NE","~","")) | BG11: =IF(BF11="","",IF(BF11="NE","",(IFERROR(IF(ISNUMBER(BF11),BF11,VALUE(BF11)),0)/2)*$F11*$F$5*20)) | BH11: =IF(BF11="","◄",IF(BF11="NE","~","")) | BJ11: =IF(BI11="","",IF(BI11="NE","",(IFERROR(IF(ISNUMBER(BI11),BI11,VALUE(BI11)),0)/2)*$F11*$F$5*20)) | BK11: =IF(BI11="","◄",IF(BI11="NE","~","")) | BM11: =IF(BL11="","",IF(BL11="NE","",(IFERROR(IF(ISNUMBER(BL11),BL11,VALUE(BL11)),0)/2)*$F11*$F$5*20)) | BN11: =IF(BL11="","◄",IF(BL11="NE","~","")) | BP11: =IF(BO11="","",IF(BO11="NE","",(IFERROR(IF(ISNUMBER(BO11),BO11,VALUE(BO11)),0)/2)*$F11*$F$5*20)) | BQ11: =IF(BO11="","◄",IF(BO11="NE","~","")) | BS11: =IF(BR11="","",IF(BR11="NE","",(IFERROR(IF(ISNUMBER(BR11),BR11,VALUE(BR11)),0)/2)*$F11*$F$5*20)) | BT11: =IF(BR11="","◄",IF(BR11="NE","~","")) | BV11: =IF(BU11="","",IF(BU11="NE","",(IFERROR(IF(ISNUMBER(BU11),BU11,VALUE(BU11)),0)/2)*$F11*$F$5*20)) | BW11: =IF(BU11="","◄",IF(BU11="NE","~","")) | BY11: =IF(BX11="","",IF(BX11="NE","",(IFERROR(IF(ISNUMBER(BX11),BX11,VALUE(BX11)),0)/2)*$F11*$F$5*20)) | BZ11: =IF(BX11="","◄",IF(BX11="NE","~","")) | CB11: =IF(CA11="","",IF(CA11="NE","",(IFERROR(IF(ISNUMBER(CA11),CA11,VALUE(CA11)),0)/2)*$F11*$F$5*20)) | CC11: =IF(CA11="","◄",IF(CA11="NE","~","")) | CE11: =IF(CD11="","",IF(CD11="NE","",(IFERROR(IF(ISNUMBER(CD11),CD11,VALUE(CD11)),0)/2)*$F11*$F$5*20)) | CF11: =IF(CD11="","◄",IF(CD11="NE","~","")) | CH11: =IF(CG11="","",IF(CG11="NE","",(IFERROR(IF(ISNUMBER(CG11),CG11,VALUE(CG11)),0)/2)*$F11*$F$5*20)) | CI11: =IF(CG11="","◄",IF(CG11="NE","~","")) | CK11: =IF(CJ11="","",IF(CJ11="NE","",(IFERROR(IF(ISNUMBER(CJ11),CJ11,VALUE(CJ11)),0)/2)*$F11*$F$5*20)) | CL11: =IF(CJ11="","◄",IF(CJ11="NE","~","")) | CN11: =IF(CM11="","",IF(CM11="NE","",(IFERROR(IF(ISNUMBER(CM11),CM11,VALUE(CM11)),0)/2)*$F11*$F$5*20)) | CO11: =IF(CM11="","◄",IF(CM11="NE","~","")) | CQ11: =IF(CP11="","",IF(CP11="NE","",(IFERROR(IF(ISNUMBER(CP11),CP11,VALUE(CP11)),0)/2)*$F11*$F$5*20)) | CR11: =IF(CP11="","◄",IF(CP11="NE","~",""))
A12: 7 | B12: P1 | C12: Q1.4 | D12: Critère | E12: Boue Activée justifiée : lit roseaux trop grand, biofiltre trop énergivore et trop cher. | F12: 0.1 | H12: =IF(G12="","",IF(G12="NE","",(IFERROR(IF(ISNUMBER(G12),G12,VALUE(G12)),0)/2)*$F12*$F$5*20)) | I12: =IF(G12="","◄",IF(G12="NE","~","")) | K12: =IF(J12="","",IF(J12="NE","",(IFERROR(IF(ISNUMBER(J12),J12,VALUE(J12)),0)/2)*$F12*$F$5*20)) | L12: =IF(J12="","◄",IF(J12="NE","~","")) | N12: =IF(M12="","",IF(M12="NE","",(IFERROR(IF(ISNUMBER(M12),M12,VALUE(M12)),0)/2)*$F12*$F$5*20)) | O12: =IF(M12="","◄",IF(M12="NE","~","")) | Q12: =IF(P12="","",IF(P12="NE","",(IFERROR(IF(ISNUMBER(P12),P12,VALUE(P12)),0)/2)*$F12*$F$5*20)) | R12: =IF(P12="","◄",IF(P12="NE","~","")) | T12: =IF(S12="","",IF(S12="NE","",(IFERROR(IF(ISNUMBER(S12),S12,VALUE(S12)),0)/2)*$F12*$F$5*20)) | U12: =IF(S12="","◄",IF(S12="NE","~","")) | W12: =IF(V12="","",IF(V12="NE","",(IFERROR(IF(ISNUMBER(V12),V12,VALUE(V12)),0)/2)*$F12*$F$5*20)) | X12: =IF(V12="","◄",IF(V12="NE","~","")) | Z12: =IF(Y12="","",IF(Y12="NE","",(IFERROR(IF(ISNUMBER(Y12),Y12,VALUE(Y12)),0)/2)*$F12*$F$5*20)) | AA12: =IF(Y12="","◄",IF(Y12="NE","~","")) | AC12: =IF(AB12="","",IF(AB12="NE","",(IFERROR(IF(ISNUMBER(AB12),AB12,VALUE(AB12)),0)/2)*$F12*$F$5*20)) | AD12: =IF(AB12="","◄",IF(AB12="NE","~","")) | AF12: =IF(AE12="","",IF(AE12="NE","",(IFERROR(IF(ISNUMBER(AE12),AE12,VALUE(AE12)),0)/2)*$F12*$F$5*20)) | AG12: =IF(AE12="","◄",IF(AE12="NE","~","")) | AI12: =IF(AH12="","",IF(AH12="NE","",(IFERROR(IF(ISNUMBER(AH12),AH12,VALUE(AH12)),0)/2)*$F12*$F$5*20)) | AJ12: =IF(AH12="","◄",IF(AH12="NE","~","")) | AL12: =IF(AK12="","",IF(AK12="NE","",(IFERROR(IF(ISNUMBER(AK12),AK12,VALUE(AK12)),0)/2)*$F12*$F$5*20)) | AM12: =IF(AK12="","◄",IF(AK12="NE","~","")) | AO12: =IF(AN12="","",IF(AN12="NE","",(IFERROR(IF(ISNUMBER(AN12),AN12,VALUE(AN12)),0)/2)*$F12*$F$5*20)) | AP12: =IF(AN12="","◄",IF(AN12="NE","~","")) | AR12: =IF(AQ12="","",IF(AQ12="NE","",(IFERROR(IF(ISNUMBER(AQ12),AQ12,VALUE(AQ12)),0)/2)*$F12*$F$5*20)) | AS12: =IF(AQ12="","◄",IF(AQ12="NE","~","")) | AU12: =IF(AT12="","",IF(AT12="NE","",(IFERROR(IF(ISNUMBER(AT12),AT12,VALUE(AT12)),0)/2)*$F12*$F$5*20)) | AV12: =IF(AT12="","◄",IF(AT12="NE","~","")) | AX12: =IF(AW12="","",IF(AW12="NE","",(IFERROR(IF(ISNUMBER(AW12),AW12,VALUE(AW12)),0)/2)*$F12*$F$5*20)) | AY12: =IF(AW12="","◄",IF(AW12="NE","~","")) | BA12: =IF(AZ12="","",IF(AZ12="NE","",(IFERROR(IF(ISNUMBER(AZ12),AZ12,VALUE(AZ12)),0)/2)*$F12*$F$5*20)) | BB12: =IF(AZ12="","◄",IF(AZ12="NE","~","")) | BD12: =IF(BC12="","",IF(BC12="NE","",(IFERROR(IF(ISNUMBER(BC12),BC12,VALUE(BC12)),0)/2)*$F12*$F$5*20)) | BE12: =IF(BC12="","◄",IF(BC12="NE","~","")) | BG12: =IF(BF12="","",IF(BF12="NE","",(IFERROR(IF(ISNUMBER(BF12),BF12,VALUE(BF12)),0)/2)*$F12*$F$5*20)) | BH12: =IF(BF12="","◄",IF(BF12="NE","~","")) | BJ12: =IF(BI12="","",IF(BI12="NE","",(IFERROR(IF(ISNUMBER(BI12),BI12,VALUE(BI12)),0)/2)*$F12*$F$5*20)) | BK12: =IF(BI12="","◄",IF(BI12="NE","~","")) | BM12: =IF(BL12="","",IF(BL12="NE","",(IFERROR(IF(ISNUMBER(BL12),BL12,VALUE(BL12)),0)/2)*$F12*$F$5*20)) | BN12: =IF(BL12="","◄",IF(BL12="NE","~","")) | BP12: =IF(BO12="","",IF(BO12="NE","",(IFERROR(IF(ISNUMBER(BO12),BO12,VALUE(BO12)),0)/2)*$F12*$F$5*20)) | BQ12: =IF(BO12="","◄",IF(BO12="NE","~","")) | BS12: =IF(BR12="","",IF(BR12="NE","",(IFERROR(IF(ISNUMBER(BR12),BR12,VALUE(BR12)),0)/2)*$F12*$F$5*20)) | BT12: =IF(BR12="","◄",IF(BR12="NE","~","")) | BV12: =IF(BU12="","",IF(BU12="NE","",(IFERROR(IF(ISNUMBER(BU12),BU12,VALUE(BU12)),0)/2)*$F12*$F$5*20)) | BW12: =IF(BU12="","◄",IF(BU12="NE","~","")) | BY12: =IF(BX12="","",IF(BX12="NE","",(IFERROR(IF(ISNUMBER(BX12),BX12,VALUE(BX12)),0)/2)*$F12*$F$5*20)) | BZ12: =IF(BX12="","◄",IF(BX12="NE","~","")) | CB12: =IF(CA12="","",IF(CA12="NE","",(IFERROR(IF(ISNUMBER(CA12),CA12,VALUE(CA12)),0)/2)*$F12*$F$5*20)) | CC12: =IF(CA12="","◄",IF(CA12="NE","~","")) | CE12: =IF(CD12="","",IF(CD12="NE","",(IFERROR(IF(ISNUMBER(CD12),CD12,VALUE(CD12)),0)/2)*$F12*$F$5*20)) | CF12: =IF(CD12="","◄",IF(CD12="NE","~","")) | CH12: =IF(CG12="","",IF(CG12="NE","",(IFERROR(IF(ISNUMBER(CG12),CG12,VALUE(CG12)),0)/2)*$F12*$F$5*20)) | CI12: =IF(CG12="","◄",IF(CG12="NE","~","")) | CK12: =IF(CJ12="","",IF(CJ12="NE","",(IFERROR(IF(ISNUMBER(CJ12),CJ12,VALUE(CJ12)),0)/2)*$F12*$F$5*20)) | CL12: =IF(CJ12="","◄",IF(CJ12="NE","~","")) | CN12: =IF(CM12="","",IF(CM12="NE","",(IFERROR(IF(ISNUMBER(CM12),CM12,VALUE(CM12)),0)/2)*$F12*$F$5*20)) | CO12: =IF(CM12="","◄",IF(CM12="NE","~","")) | CQ12: =IF(CP12="","",IF(CP12="NE","",(IFERROR(IF(ISNUMBER(CP12),CP12,VALUE(CP12)),0)/2)*$F12*$F$5*20)) | CR12: =IF(CP12="","◄",IF(CP12="NE","~",""))
B13: P2 | D13: Partie | E13: Comment la digestion des boues améliore-t-elle les performances d'une STEU dans une démarche DD ? | F13: 0.25 | H13: =IFERROR(SUM(H14:H21)/(SUMPRODUCT(($F$14:$F$21)*(G14:G21<>"")*(G14:G21<>"NE"))*$F$13),"") | K13: =IFERROR(SUM(K14:K21)/(SUMPRODUCT(($F$14:$F$21)*(J14:J21<>"")*(J14:J21<>"NE"))*$F$13),"") | N13: =IFERROR(SUM(N14:N21)/(SUMPRODUCT(($F$14:$F$21)*(M14:M21<>"")*(M14:M21<>"NE"))*$F$13),"") | Q13: =IFERROR(SUM(Q14:Q21)/(SUMPRODUCT(($F$14:$F$21)*(P14:P21<>"")*(P14:P21<>"NE"))*$F$13),"") | T13: =IFERROR(SUM(T14:T21)/(SUMPRODUCT(($F$14:$F$21)*(S14:S21<>"")*(S14:S21<>"NE"))*$F$13),"") | W13: =IFERROR(SUM(W14:W21)/(SUMPRODUCT(($F$14:$F$21)*(V14:V21<>"")*(V14:V21<>"NE"))*$F$13),"") | Z13: =IFERROR(SUM(Z14:Z21)/(SUMPRODUCT(($F$14:$F$21)*(Y14:Y21<>"")*(Y14:Y21<>"NE"))*$F$13),"") | AC13: =IFERROR(SUM(AC14:AC21)/(SUMPRODUCT(($F$14:$F$21)*(AB14:AB21<>"")*(AB14:AB21<>"NE"))*$F$13),"") | AF13: =IFERROR(SUM(AF14:AF21)/(SUMPRODUCT(($F$14:$F$21)*(AE14:AE21<>"")*(AE14:AE21<>"NE"))*$F$13),"") | AI13: =IFERROR(SUM(AI14:AI21)/(SUMPRODUCT(($F$14:$F$21)*(AH14:AH21<>"")*(AH14:AH21<>"NE"))*$F$13),"") | AL13: =IFERROR(SUM(AL14:AL21)/(SUMPRODUCT(($F$14:$F$21)*(AK14:AK21<>"")*(AK14:AK21<>"NE"))*$F$13),"") | AO13: =IFERROR(SUM(AO14:AO21)/(SUMPRODUCT(($F$14:$F$21)*(AN14:AN21<>"")*(AN14:AN21<>"NE"))*$F$13),"") | AR13: =IFERROR(SUM(AR14:AR21)/(SUMPRODUCT(($F$14:$F$21)*(AQ14:AQ21<>"")*(AQ14:AQ21<>"NE"))*$F$13),"") | AU13: =IFERROR(SUM(AU14:AU21)/(SUMPRODUCT(($F$14:$F$21)*(AT14:AT21<>"")*(AT14:AT21<>"NE"))*$F$13),"") | AX13: =IFERROR(SUM(AX14:AX21)/(SUMPRODUCT(($F$14:$F$21)*(AW14:AW21<>"")*(AW14:AW21<>"NE"))*$F$13),"") | BA13: =IFERROR(SUM(BA14:BA21)/(SUMPRODUCT(($F$14:$F$21)*(AZ14:AZ21<>"")*(AZ14:AZ21<>"NE"))*$F$13),"") | BD13: =IFERROR(SUM(BD14:BD21)/(SUMPRODUCT(($F$14:$F$21)*(BC14:BC21<>"")*(BC14:BC21<>"NE"))*$F$13),"") | BG13: =IFERROR(SUM(BG14:BG21)/(SUMPRODUCT(($F$14:$F$21)*(BF14:BF21<>"")*(BF14:BF21<>"NE"))*$F$13),"") | BJ13: =IFERROR(SUM(BJ14:BJ21)/(SUMPRODUCT(($F$14:$F$21)*(BI14:BI21<>"")*(BI14:BI21<>"NE"))*$F$13),"") | BM13: =IFERROR(SUM(BM14:BM21)/(SUMPRODUCT(($F$14:$F$21)*(BL14:BL21<>"")*(BL14:BL21<>"NE"))*$F$13),"") | BP13: =IFERROR(SUM(BP14:BP21)/(SUMPRODUCT(($F$14:$F$21)*(BO14:BO21<>"")*(BO14:BO21<>"NE"))*$F$13),"") | BS13: =IFERROR(SUM(BS14:BS21)/(SUMPRODUCT(($F$14:$F$21)*(BR14:BR21<>"")*(BR14:BR21<>"NE"))*$F$13),"") | BV13: =IFERROR(SUM(BV14:BV21)/(SUMPRODUCT(($F$14:$F$21)*(BU14:BU21<>"")*(BU14:BU21<>"NE"))*$F$13),"") | BY13: =IFERROR(SUM(BY14:BY21)/(SUMPRODUCT(($F$14:$F$21)*(BX14:BX21<>"")*(BX14:BX21<>"NE"))*$F$13),"") | CB13: =IFERROR(SUM(CB14:CB21)/(SUMPRODUCT(($F$14:$F$21)*(CA14:CA21<>"")*(CA14:CA21<>"NE"))*$F$13),"") | CE13: =IFERROR(SUM(CE14:CE21)/(SUMPRODUCT(($F$14:$F$21)*(CD14:CD21<>"")*(CD14:CD21<>"NE"))*$F$13),"") | CH13: =IFERROR(SUM(CH14:CH21)/(SUMPRODUCT(($F$14:$F$21)*(CG14:CG21<>"")*(CG14:CG21<>"NE"))*$F$13),"") | CK13: =IFERROR(SUM(CK14:CK21)/(SUMPRODUCT(($F$14:$F$21)*(CJ14:CJ21<>"")*(CJ14:CJ21<>"NE"))*$F$13),"") | CN13: =IFERROR(SUM(CN14:CN21)/(SUMPRODUCT(($F$14:$F$21)*(CM14:CM21<>"")*(CM14:CM21<>"NE"))*$F$13),"") | CQ13: =IFERROR(SUM(CQ14:CQ21)/(SUMPRODUCT(($F$14:$F$21)*(CP14:CP21<>"")*(CP14:CP21<>"NE"))*$F$13),"")
A14: 8 | B14: P2 | C14: Q2.1 | D14: Critère | E14: Type 1 : flux entrant = énergie électrique. | F14: 0.1 | H14: =IF(G14="","",IF(G14="NE","",(IFERROR(IF(ISNUMBER(G14),G14,VALUE(G14)),0)/2)*$F14*$F$13*20)) | I14: =IF(G14="","◄",IF(G14="NE","~","")) | K14: =IF(J14="","",IF(J14="NE","",(IFERROR(IF(ISNUMBER(J14),J14,VALUE(J14)),0)/2)*$F14*$F$13*20)) | L14: =IF(J14="","◄",IF(J14="NE","~","")) | N14: =IF(M14="","",IF(M14="NE","",(IFERROR(IF(ISNUMBER(M14),M14,VALUE(M14)),0)/2)*$F14*$F$13*20)) | O14: =IF(M14="","◄",IF(M14="NE","~","")) | Q14: =IF(P14="","",IF(P14="NE","",(IFERROR(IF(ISNUMBER(P14),P14,VALUE(P14)),0)/2)*$F14*$F$13*20)) | R14: =IF(P14="","◄",IF(P14="NE","~","")) | T14: =IF(S14="","",IF(S14="NE","",(IFERROR(IF(ISNUMBER(S14),S14,VALUE(S14)),0)/2)*$F14*$F$13*20)) | U14: =IF(S14="","◄",IF(S14="NE","~","")) | W14: =IF(V14="","",IF(V14="NE","",(IFERROR(IF(ISNUMBER(V14),V14,VALUE(V14)),0)/2)*$F14*$F$13*20)) | X14: =IF(V14="","◄",IF(V14="NE","~","")) | Z14: =IF(Y14="","",IF(Y14="NE","",(IFERROR(IF(ISNUMBER(Y14),Y14,VALUE(Y14)),0)/2)*$F14*$F$13*20)) | AA14: =IF(Y14="","◄",IF(Y14="NE","~","")) | AC14: =IF(AB14="","",IF(AB14="NE","",(IFERROR(IF(ISNUMBER(AB14),AB14,VALUE(AB14)),0)/2)*$F14*$F$13*20)) | AD14: =IF(AB14="","◄",IF(AB14="NE","~","")) | AF14: =IF(AE14="","",IF(AE14="NE","",(IFERROR(IF(ISNUMBER(AE14),AE14,VALUE(AE14)),0)/2)*$F14*$F$13*20)) | AG14: =IF(AE14="","◄",IF(AE14="NE","~","")) | AI14: =IF(AH14="","",IF(AH14="NE","",(IFERROR(IF(ISNUMBER(AH14),AH14,VALUE(AH14)),0)/2)*$F14*$F$13*20)) | AJ14: =IF(AH14="","◄",IF(AH14="NE","~","")) | AL14: =IF(AK14="","",IF(AK14="NE","",(IFERROR(IF(ISNUMBER(AK14),AK14,VALUE(AK14)),0)/2)*$F14*$F$13*20)) | AM14: =IF(AK14="","◄",IF(AK14="NE","~","")) | AO14: =IF(AN14="","",IF(AN14="NE","",(IFERROR(IF(ISNUMBER(AN14),AN14,VALUE(AN14)),0)/2)*$F14*$F$13*20)) | AP14: =IF(AN14="","◄",IF(AN14="NE","~","")) | AR14: =IF(AQ14="","",IF(AQ14="NE","",(IFERROR(IF(ISNUMBER(AQ14),AQ14,VALUE(AQ14)),0)/2)*$F14*$F$13*20)) | AS14: =IF(AQ14="","◄",IF(AQ14="NE","~","")) | AU14: =IF(AT14="","",IF(AT14="NE","",(IFERROR(IF(ISNUMBER(AT14),AT14,VALUE(AT14)),0)/2)*$F14*$F$13*20)) | AV14: =IF(AT14="","◄",IF(AT14="NE","~","")) | AX14: =IF(AW14="","",IF(AW14="NE","",(IFERROR(IF(ISNUMBER(AW14),AW14,VALUE(AW14)),0)/2)*$F14*$F$13*20)) | AY14: =IF(AW14="","◄",IF(AW14="NE","~","")) | BA14: =IF(AZ14="","",IF(AZ14="NE","",(IFERROR(IF(ISNUMBER(AZ14),AZ14,VALUE(AZ14)),0)/2)*$F14*$F$13*20)) | BB14: =IF(AZ14="","◄",IF(AZ14="NE","~","")) | BD14: =IF(BC14="","",IF(BC14="NE","",(IFERROR(IF(ISNUMBER(BC14),BC14,VALUE(BC14)),0)/2)*$F14*$F$13*20)) | BE14: =IF(BC14="","◄",IF(BC14="NE","~","")) | BG14: =IF(BF14="","",IF(BF14="NE","",(IFERROR(IF(ISNUMBER(BF14),BF14,VALUE(BF14)),0)/2)*$F14*$F$13*20)) | BH14: =IF(BF14="","◄",IF(BF14="NE","~","")) | BJ14: =IF(BI14="","",IF(BI14="NE","",(IFERROR(IF(ISNUMBER(BI14),BI14,VALUE(BI14)),0)/2)*$F14*$F$13*20)) | BK14: =IF(BI14="","◄",IF(BI14="NE","~","")) | BM14: =IF(BL14="","",IF(BL14="NE","",(IFERROR(IF(ISNUMBER(BL14),BL14,VALUE(BL14)),0)/2)*$F14*$F$13*20)) | BN14: =IF(BL14="","◄",IF(BL14="NE","~","")) | BP14: =IF(BO14="","",IF(BO14="NE","",(IFERROR(IF(ISNUMBER(BO14),BO14,VALUE(BO14)),0)/2)*$F14*$F$13*20)) | BQ14: =IF(BO14="","◄",IF(BO14="NE","~","")) | BS14: =IF(BR14="","",IF(BR14="NE","",(IFERROR(IF(ISNUMBER(BR14),BR14,VALUE(BR14)),0)/2)*$F14*$F$13*20)) | BT14: =IF(BR14="","◄",IF(BR14="NE","~","")) | BV14: =IF(BU14="","",IF(BU14="NE","",(IFERROR(IF(ISNUMBER(BU14),BU14,VALUE(BU14)),0)/2)*$F14*$F$13*20)) | BW14: =IF(BU14="","◄",IF(BU14="NE","~","")) | BY14: =IF(BX14="","",IF(BX14="NE","",(IFERROR(IF(ISNUMBER(BX14),BX14,VALUE(BX14)),0)/2)*$F14*$F$13*20)) | BZ14: =IF(BX14="","◄",IF(BX14="NE","~","")) | CB14: =IF(CA14="","",IF(CA14="NE","",(IFERROR(IF(ISNUMBER(CA14),CA14,VALUE(CA14)),0)/2)*$F14*$F$13*20)) | CC14: =IF(CA14="","◄",IF(CA14="NE","~","")) | CE14: =IF(CD14="","",IF(CD14="NE","",(IFERROR(IF(ISNUMBER(CD14),CD14,VALUE(CD14)),0)/2)*$F14*$F$13*20)) | CF14: =IF(CD14="","◄",IF(CD14="NE","~","")) | CH14: =IF(CG14="","",IF(CG14="NE","",(IFERROR(IF(ISNUMBER(CG14),CG14,VALUE(CG14)),0)/2)*$F14*$F$13*20)) | CI14: =IF(CG14="","◄",IF(CG14="NE","~","")) | CK14: =IF(CJ14="","",IF(CJ14="NE","",(IFERROR(IF(ISNUMBER(CJ14),CJ14,VALUE(CJ14)),0)/2)*$F14*$F$13*20)) | CL14: =IF(CJ14="","◄",IF(CJ14="NE","~","")) | CN14: =IF(CM14="","",IF(CM14="NE","",(IFERROR(IF(ISNUMBER(CM14),CM14,VALUE(CM14)),0)/2)*$F14*$F$13*20)) | CO14: =IF(CM14="","◄",IF(CM14="NE","~","")) | CQ14: =IF(CP14="","",IF(CP14="NE","",(IFERROR(IF(ISNUMBER(CP14),CP14,VALUE(CP14)),0)/2)*$F14*$F$13*20)) | CR14: =IF(CP14="","◄",IF(CP14="NE","~",""))
A15: 9 | B15: P2 | C15: Q2.1 | D15: Critère | E15: Type 2 : entrants = énergie élec + gaz GRDF ; sortants = méthane (GRDF) + thermique perdue (torchère). | F15: 0.1 | H15: =IF(G15="","",IF(G15="NE","",(IFERROR(IF(ISNUMBER(G15),G15,VALUE(G15)),0)/2)*$F15*$F$13*20)) | I15: =IF(G15="","◄",IF(G15="NE","~","")) | K15: =IF(J15="","",IF(J15="NE","",(IFERROR(IF(ISNUMBER(J15),J15,VALUE(J15)),0)/2)*$F15*$F$13*20)) | L15: =IF(J15="","◄",IF(J15="NE","~","")) | N15: =IF(M15="","",IF(M15="NE","",(IFERROR(IF(ISNUMBER(M15),M15,VALUE(M15)),0)/2)*$F15*$F$13*20)) | O15: =IF(M15="","◄",IF(M15="NE","~","")) | Q15: =IF(P15="","",IF(P15="NE","",(IFERROR(IF(ISNUMBER(P15),P15,VALUE(P15)),0)/2)*$F15*$F$13*20)) | R15: =IF(P15="","◄",IF(P15="NE","~","")) | T15: =IF(S15="","",IF(S15="NE","",(IFERROR(IF(ISNUMBER(S15),S15,VALUE(S15)),0)/2)*$F15*$F$13*20)) | U15: =IF(S15="","◄",IF(S15="NE","~","")) | W15: =IF(V15="","",IF(V15="NE","",(IFERROR(IF(ISNUMBER(V15),V15,VALUE(V15)),0)/2)*$F15*$F$13*20)) | X15: =IF(V15="","◄",IF(V15="NE","~","")) | Z15: =IF(Y15="","",IF(Y15="NE","",(IFERROR(IF(ISNUMBER(Y15),Y15,VALUE(Y15)),0)/2)*$F15*$F$13*20)) | AA15: =IF(Y15="","◄",IF(Y15="NE","~","")) | AC15: =IF(AB15="","",IF(AB15="NE","",(IFERROR(IF(ISNUMBER(AB15),AB15,VALUE(AB15)),0)/2)*$F15*$F$13*20)) | AD15: =IF(AB15="","◄",IF(AB15="NE","~","")) | AF15: =IF(AE15="","",IF(AE15="NE","",(IFERROR(IF(ISNUMBER(AE15),AE15,VALUE(AE15)),0)/2)*$F15*$F$13*20)) | AG15: =IF(AE15="","◄",IF(AE15="NE","~","")) | AI15: =IF(AH15="","",IF(AH15="NE","",(IFERROR(IF(ISNUMBER(AH15),AH15,VALUE(AH15)),0)/2)*$F15*$F$13*20)) | AJ15: =IF(AH15="","◄",IF(AH15="NE","~","")) | AL15: =IF(AK15="","",IF(AK15="NE","",(IFERROR(IF(ISNUMBER(AK15),AK15,VALUE(AK15)),0)/2)*$F15*$F$13*20)) | AM15: =IF(AK15="","◄",IF(AK15="NE","~","")) | AO15: =IF(AN15="","",IF(AN15="NE","",(IFERROR(IF(ISNUMBER(AN15),AN15,VALUE(AN15)),0)/2)*$F15*$F$13*20)) | AP15: =IF(AN15="","◄",IF(AN15="NE","~","")) | AR15: =IF(AQ15="","",IF(AQ15="NE","",(IFERROR(IF(ISNUMBER(AQ15),AQ15,VALUE(AQ15)),0)/2)*$F15*$F$13*20)) | AS15: =IF(AQ15="","◄",IF(AQ15="NE","~","")) | AU15: =IF(AT15="","",IF(AT15="NE","",(IFERROR(IF(ISNUMBER(AT15),AT15,VALUE(AT15)),0)/2)*$F15*$F$13*20)) | AV15: =IF(AT15="","◄",IF(AT15="NE","~","")) | AX15: =IF(AW15="","",IF(AW15="NE","",(IFERROR(IF(ISNUMBER(AW15),AW15,VALUE(AW15)),0)/2)*$F15*$F$13*20)) | AY15: =IF(AW15="","◄",IF(AW15="NE","~","")) | BA15: =IF(AZ15="","",IF(AZ15="NE","",(IFERROR(IF(ISNUMBER(AZ15),AZ15,VALUE(AZ15)),0)/2)*$F15*$F$13*20)) | BB15: =IF(AZ15="","◄",IF(AZ15="NE","~","")) | BD15: =IF(BC15="","",IF(BC15="NE","",(IFERROR(IF(ISNUMBER(BC15),BC15,VALUE(BC15)),0)/2)*$F15*$F$13*20)) | BE15: =IF(BC15="","◄",IF(BC15="NE","~","")) | BG15: =IF(BF15="","",IF(BF15="NE","",(IFERROR(IF(ISNUMBER(BF15),BF15,VALUE(BF15)),0)/2)*$F15*$F$13*20)) | BH15: =IF(BF15="","◄",IF(BF15="NE","~","")) | BJ15: =IF(BI15="","",IF(BI15="NE","",(IFERROR(IF(ISNUMBER(BI15),BI15,VALUE(BI15)),0)/2)*$F15*$F$13*20)) | BK15: =IF(BI15="","◄",IF(BI15="NE","~","")) | BM15: =IF(BL15="","",IF(BL15="NE","",(IFERROR(IF(ISNUMBER(BL15),BL15,VALUE(BL15)),0)/2)*$F15*$F$13*20)) | BN15: =IF(BL15="","◄",IF(BL15="NE","~","")) | BP15: =IF(BO15="","",IF(BO15="NE","",(IFERROR(IF(ISNUMBER(BO15),BO15,VALUE(BO15)),0)/2)*$F15*$F$13*20)) | BQ15: =IF(BO15="","◄",IF(BO15="NE","~","")) | BS15: =IF(BR15="","",IF(BR15="NE","",(IFERROR(IF(ISNUMBER(BR15),BR15,VALUE(BR15)),0)/2)*$F15*$F$13*20)) | BT15: =IF(BR15="","◄",IF(BR15="NE","~","")) | BV15: =IF(BU15="","",IF(BU15="NE","",(IFERROR(IF(ISNUMBER(BU15),BU15,VALUE(BU15)),0)/2)*$F15*$F$13*20)) | BW15: =IF(BU15="","◄",IF(BU15="NE","~","")) | BY15: =IF(BX15="","",IF(BX15="NE","",(IFERROR(IF(ISNUMBER(BX15),BX15,VALUE(BX15)),0)/2)*$F15*$F$13*20)) | BZ15: =IF(BX15="","◄",IF(BX15="NE","~","")) | CB15: =IF(CA15="","",IF(CA15="NE","",(IFERROR(IF(ISNUMBER(CA15),CA15,VALUE(CA15)),0)/2)*$F15*$F$13*20)) | CC15: =IF(CA15="","◄",IF(CA15="NE","~","")) | CE15: =IF(CD15="","",IF(CD15="NE","",(IFERROR(IF(ISNUMBER(CD15),CD15,VALUE(CD15)),0)/2)*$F15*$F$13*20)) | CF15: =IF(CD15="","◄",IF(CD15="NE","~","")) | CH15: =IF(CG15="","",IF(CG15="NE","",(IFERROR(IF(ISNUMBER(CG15),CG15,VALUE(CG15)),0)/2)*$F15*$F$13*20)) | CI15: =IF(CG15="","◄",IF(CG15="NE","~","")) | CK15: =IF(CJ15="","",IF(CJ15="NE","",(IFERROR(IF(ISNUMBER(CJ15),CJ15,VALUE(CJ15)),0)/2)*$F15*$F$13*20)) | CL15: =IF(CJ15="","◄",IF(CJ15="NE","~","")) | CN15: =IF(CM15="","",IF(CM15="NE","",(IFERROR(IF(ISNUMBER(CM15),CM15,VALUE(CM15)),0)/2)*$F15*$F$13*20)) | CO15: =IF(CM15="","◄",IF(CM15="NE","~","")) | CQ15: =IF(CP15="","",IF(CP15="NE","",(IFERROR(IF(ISNUMBER(CP15),CP15,VALUE(CP15)),0)/2)*$F15*$F$13*20)) | CR15: =IF(CP15="","◄",IF(CP15="NE","~",""))
A16: 10 | B16: P2 | C16: Q2.2 | D16: Critère | E16: Calcul : 6 160 000 × 0,1 = 616 000 kgeq.CO₂/an. | F16: 0.1 | H16: =IF(G16="","",IF(G16="NE","",(IFERROR(IF(ISNUMBER(G16),G16,VALUE(G16)),0)/2)*$F16*$F$13*20)) | I16: =IF(G16="","◄",IF(G16="NE","~","")) | K16: =IF(J16="","",IF(J16="NE","",(IFERROR(IF(ISNUMBER(J16),J16,VALUE(J16)),0)/2)*$F16*$F$13*20)) | L16: =IF(J16="","◄",IF(J16="NE","~","")) | N16: =IF(M16="","",IF(M16="NE","",(IFERROR(IF(ISNUMBER(M16),M16,VALUE(M16)),0)/2)*$F16*$F$13*20)) | O16: =IF(M16="","◄",IF(M16="NE","~","")) | Q16: =IF(P16="","",IF(P16="NE","",(IFERROR(IF(ISNUMBER(P16),P16,VALUE(P16)),0)/2)*$F16*$F$13*20)) | R16: =IF(P16="","◄",IF(P16="NE","~","")) | T16: =IF(S16="","",IF(S16="NE","",(IFERROR(IF(ISNUMBER(S16),S16,VALUE(S16)),0)/2)*$F16*$F$13*20)) | U16: =IF(S16="","◄",IF(S16="NE","~","")) | W16: =IF(V16="","",IF(V16="NE","",(IFERROR(IF(ISNUMBER(V16),V16,VALUE(V16)),0)/2)*$F16*$F$13*20)) | X16: =IF(V16="","◄",IF(V16="NE","~","")) | Z16: =IF(Y16="","",IF(Y16="NE","",(IFERROR(IF(ISNUMBER(Y16),Y16,VALUE(Y16)),0)/2)*$F16*$F$13*20)) | AA16: =IF(Y16="","◄",IF(Y16="NE","~","")) | AC16: =IF(AB16="","",IF(AB16="NE","",(IFERROR(IF(ISNUMBER(AB16),AB16,VALUE(AB16)),0)/2)*$F16*$F$13*20)) | AD16: =IF(AB16="","◄",IF(AB16="NE","~","")) | AF16: =IF(AE16="","",IF(AE16="NE","",(IFERROR(IF(ISNUMBER(AE16),AE16,VALUE(AE16)),0)/2)*$F16*$F$13*20)) | AG16: =IF(AE16="","◄",IF(AE16="NE","~","")) | AI16: =IF(AH16="","",IF(AH16="NE","",(IFERROR(IF(ISNUMBER(AH16),AH16,VALUE(AH16)),0)/2)*$F16*$F$13*20)) | AJ16: =IF(AH16="","◄",IF(AH16="NE","~","")) | AL16: =IF(AK16="","",IF(AK16="NE","",(IFERROR(IF(ISNUMBER(AK16),AK16,VALUE(AK16)),0)/2)*$F16*$F$13*20)) | AM16: =IF(AK16="","◄",IF(AK16="NE","~","")) | AO16: =IF(AN16="","",IF(AN16="NE","",(IFERROR(IF(ISNUMBER(AN16),AN16,VALUE(AN16)),0)/2)*$F16*$F$13*20)) | AP16: =IF(AN16="","◄",IF(AN16="NE","~","")) | AR16: =IF(AQ16="","",IF(AQ16="NE","",(IFERROR(IF(ISNUMBER(AQ16),AQ16,VALUE(AQ16)),0)/2)*$F16*$F$13*20)) | AS16: =IF(AQ16="","◄",IF(AQ16="NE","~","")) | AU16: =IF(AT16="","",IF(AT16="NE","",(IFERROR(IF(ISNUMBER(AT16),AT16,VALUE(AT16)),0)/2)*$F16*$F$13*20)) | AV16: =IF(AT16="","◄",IF(AT16="NE","~","")) | AX16: =IF(AW16="","",IF(AW16="NE","",(IFERROR(IF(ISNUMBER(AW16),AW16,VALUE(AW16)),0)/2)*$F16*$F$13*20)) | AY16: =IF(AW16="","◄",IF(AW16="NE","~","")) | BA16: =IF(AZ16="","",IF(AZ16="NE","",(IFERROR(IF(ISNUMBER(AZ16),AZ16,VALUE(AZ16)),0)/2)*$F16*$F$13*20)) | BB16: =IF(AZ16="","◄",IF(AZ16="NE","~","")) | BD16: =IF(BC16="","",IF(BC16="NE","",(IFERROR(IF(ISNUMBER(BC16),BC16,VALUE(BC16)),0)/2)*$F16*$F$13*20)) | BE16: =IF(BC16="","◄",IF(BC16="NE","~","")) | BG16: =IF(BF16="","",IF(BF16="NE","",(IFERROR(IF(ISNUMBER(BF16),BF16,VALUE(BF16)),0)/2)*$F16*$F$13*20)) | BH16: =IF(BF16="","◄",IF(BF16="NE","~","")) | BJ16: =IF(BI16="","",IF(BI16="NE","",(IFERROR(IF(ISNUMBER(BI16),BI16,VALUE(BI16)),0)/2)*$F16*$F$13*20)) | BK16: =IF(BI16="","◄",IF(BI16="NE","~","")) | BM16: =IF(BL16="","",IF(BL16="NE","",(IFERROR(IF(ISNUMBER(BL16),BL16,VALUE(BL16)),0)/2)*$F16*$F$13*20)) | BN16: =IF(BL16="","◄",IF(BL16="NE","~","")) | BP16: =IF(BO16="","",IF(BO16="NE","",(IFERROR(IF(ISNUMBER(BO16),BO16,VALUE(BO16)),0)/2)*$F16*$F$13*20)) | BQ16: =IF(BO16="","◄",IF(BO16="NE","~","")) | BS16: =IF(BR16="","",IF(BR16="NE","",(IFERROR(IF(ISNUMBER(BR16),BR16,VALUE(BR16)),0)/2)*$F16*$F$13*20)) | BT16: =IF(BR16="","◄",IF(BR16="NE","~","")) | BV16: =IF(BU16="","",IF(BU16="NE","",(IFERROR(IF(ISNUMBER(BU16),BU16,VALUE(BU16)),0)/2)*$F16*$F$13*20)) | BW16: =IF(BU16="","◄",IF(BU16="NE","~","")) | BY16: =IF(BX16="","",IF(BX16="NE","",(IFERROR(IF(ISNUMBER(BX16),BX16,VALUE(BX16)),0)/2)*$F16*$F$13*20)) | BZ16: =IF(BX16="","◄",IF(BX16="NE","~","")) | CB16: =IF(CA16="","",IF(CA16="NE","",(IFERROR(IF(ISNUMBER(CA16),CA16,VALUE(CA16)),0)/2)*$F16*$F$13*20)) | CC16: =IF(CA16="","◄",IF(CA16="NE","~","")) | CE16: =IF(CD16="","",IF(CD16="NE","",(IFERROR(IF(ISNUMBER(CD16),CD16,VALUE(CD16)),0)/2)*$F16*$F$13*20)) | CF16: =IF(CD16="","◄",IF(CD16="NE","~","")) | CH16: =IF(CG16="","",IF(CG16="NE","",(IFERROR(IF(ISNUMBER(CG16),CG16,VALUE(CG16)),0)/2)*$F16*$F$13*20)) | CI16: =IF(CG16="","◄",IF(CG16="NE","~","")) | CK16: =IF(CJ16="","",IF(CJ16="NE","",(IFERROR(IF(ISNUMBER(CJ16),CJ16,VALUE(CJ16)),0)/2)*$F16*$F$13*20)) | CL16: =IF(CJ16="","◄",IF(CJ16="NE","~","")) | CN16: =IF(CM16="","",IF(CM16="NE","",(IFERROR(IF(ISNUMBER(CM16),CM16,VALUE(CM16)),0)/2)*$F16*$F$13*20)) | CO16: =IF(CM16="","◄",IF(CM16="NE","~","")) | CQ16: =IF(CP16="","",IF(CP16="NE","",(IFERROR(IF(ISNUMBER(CP16),CP16,VALUE(CP16)),0)/2)*$F16*$F$13*20)) | CR16: =IF(CP16="","◄",IF(CP16="NE","~",""))
